Workbook

Sheet COVER
B2: DOKUMEN MANAJEMEN RISIKO
B3: Mahkamah Agung Republik Indonesia — Risk-Sim
B4: Berbasis SPIP — PP No. 60 Tahun 2008
B6: Tab | C6: Nama Sheet | D6: Fungsi | E6: Diisi Oleh
B7: MASTER | C7: Master Data & Referensi | D7: Data unit kerja, kategori, proses bisnis MA | E7: Admin Sistem
B8: KONTEKS | C8: Penetapan Konteks | D8: Kerangka MR: unit kerja, tahun, sasaran, proses bisnis | E8: Pengelola Risiko
B9: SELERA_RISIKO | C9: Penetapan Selera Risiko | D9: Threshold toleransi per 7 kategori risiko | E9: Pemilik Risiko
B10: IDENTIFIKASI | C10: Identifikasi Risiko (Lamp. 5) | D10: Daftar risiko + kode otomatis | E10: Pengelola Risiko
B11: PENYEBAB | C11: Identifikasi Penyebab (Lamp. 9) | D11: 5-Whys per risiko + kode penyebab otomatis | E11: Pengelola Risiko
B12: ANALISIS | C12: Analisis Risiko | D12: Matriks 5×5, skor inheren & residual | E12: Pengelola Risiko
B13: EVALUASI | C13: Evaluasi Risiko | D13: Prioritas + heatmap 5×5 residual | E13: Pemilik Risiko
B14: EVAL_PENG | C14: Evaluasi Pengendalian Utama | D14: Pengendalian kunci per risiko prioritas | E14: APIP
B15: PROGRAM_AUDIT | C15: Program Kerja Audit | D15: PKA per risiko kecukupan kurang/tidak memadai | E15: APIP
B16: RTP | C16: Rencana Tindak Pengendalian (Lamp. 10) | D16: Mitigasi per penyebab risiko prioritas | E16: Pengelola Risiko
B17: MATURITAS | C17: Maturitas Manajemen Risiko | D17: Penilaian kapabilitas MR level 1–5 | E17: APIP / UMR
B18: LAPORAN | C18: Laporan Eksekutif | D18: Dashboard ringkasan lintas modul | E18: Unit MR MA
B21: ⚠ Catatan Penggunaan: Workbook ini dirancang untuk SATU konteks (satu unit kerja × satu tahun). Isi sheet secara berurutan dari [1] KONTEKS hingga [9] RTP. Sheet EVALUASI, [7], [8], dan [9] otomatis menarik data — tidak perlu diisi manual selain kolom input berwarna putih.

Sheet MASTER
A1: Kode Unit | B1: Nama Unit Kerja | D1: No | E1: Kategori Risiko | F1: Kode | H1: Kode 5M | I1: Kategori Penyebab | K1: Kode Proses | L1: Kelompok Proses | M1: Sub Proses | N1: Indikator Default | P1: No | Q1: Klasifikasi SPIP | S1: Besaran | T1: Level | U1: Label
A2: KMA | B2: Ketua Mahkamah Agung | D2: 1 | E2: Strategis | F2: STR | H2: MN | I2: Manusia (Man) | K2: MA-01.01 | L2: MA-01 Pengelolaan Proses Peradilan | M2: Peningkatan Penyelesaian Perkara Tepat Waktu | N2: Persentase perkara diselesaikan tepat waktu | P2: 1 | Q2: Lingkungan Pengendalian — Komitmen terhadap kompetensi | S2: 1–5 | T2: 1 | U2: Sangat Rendah
A3: SEKMA | B3: Sekretariat Mahkamah Agung | D3: 2 | E3: Kebijakan | F3: KBJ | H3: MY | I3: Dana (Money) | K3: MA-01.02 | L3: MA-01 Pengelolaan Proses Peradilan | M3: Peningkatan putusan pendekatan keadilan restoratif | N3: Jumlah putusan restoratif | P3: 2 | Q3: Lingkungan Pengendalian — Kepemimpinan yang kondusif | S3: 6–10 | T3: 2 | U3: Rendah
A4: BAWAS | B4: Badan Pengawasan | D4: 3 | E4: Kecurangan | F4: KCR | H4: MD | I4: Metode (Method) | K4: MA-01.03 | L4: MA-01 Pengelolaan Proses Peradilan | M4: Peningkatan perkara tidak mengajukan upaya hukum | N4: Persentase perkara inkracht | P4: 3 | Q4: Lingkungan Pengendalian — Struktur organisasi | S4: 11–15 | T4: 3 | U4: Sedang
A5: DJU | B5: Direktorat Jenderal Badan Peradilan Umum | D5: 4 | E5: Bencana | F5: BNC | H5: MR | I5: Bahan (Material) | K5: MA-01.04 | L5: MA-01 Pengelolaan Proses Peradilan | M5: Peningkatan penyelesaian perkara pidana anak dengan diversi | N5: Jumlah perkara diversi | P5: 4 | Q5: Lingkungan Pengendalian — Pendelegasian wewenang dan tanggung jawab | S5: 16–19 | T5: 4 | U5: Tinggi
A6: DJMIL | B6: Direktorat Jenderal Badan Peradilan Militer | D6: 5 | E6: Kepatuhan | F6: KPT | H6: MC | I6: Mesin (Machine) | K6: MA-02.01 | L6: MA-02 Efektivitas Penyelesaian Perkara | M6: Pengiriman salinan putusan tepat waktu | N6: Persentase pengiriman tepat waktu | P6: 5 | Q6: Lingkungan Pengendalian — Kebijakan pembinaan SDM | S6: 20–25 | T6: 5 | U6: Sangat Tinggi
A7: DJTA | B7: Direktorat Jenderal Badan Peradilan TUN | D7: 6 | E7: Operasional | F7: OPS | H7: EX | I7: Eksternal | K7: MA-02.02 | L7: MA-02 Efektivitas Penyelesaian Perkara | M7: Penyelesaian perkara melalui mediasi | N7: Jumlah perkara mediasi berhasil | P7: 6 | Q7: Penilaian Risiko — Identifikasi risiko
A8: DJAG | B8: Direktorat Jenderal Badan Peradilan Agama | D8: 7 | E8: Kemitraan | F8: KMT | K8: MA-03.01 | L8: MA-03 Akses Peradilan | M8: Penyelesaian perkara prodeo | N8: Jumlah perkara prodeo diselesaikan | P8: 7 | Q8: Penilaian Risiko — Analisis risiko
A9: BALITB | B9: Badan Penelitian dan Pengembangan | K9: MA-03.02 | L9: MA-03 Akses Peradilan | M9: Penyelesaian perkara di luar gedung | N9: Jumlah sidang luar gedung | P9: 8 | Q9: Kegiatan Pengendalian — Review kinerja
A10: BADIKL | B10: Badan Diklat Teknis Hukum dan Peradilan | K10: MA-03.03 | L10: MA-03 Akses Peradilan | M10: Perkara permohonan identitas hukum | N10: Jumlah permohonan identitas | P10: 9 | Q10: Kegiatan Pengendalian — Pengendalian atas pengelolaan sistem informasi
A11: PT-JKT | B11: Pengadilan Tinggi Jakarta | K11: MA-03.04 | L11: MA-03 Akses Peradilan | M11: Layanan bantuan hukum (Posbankum) | N11: Jumlah penerima bantuan hukum | P11: 10 | Q11: Kegiatan Pengendalian — Pengendalian fisik atas aset
A12: PT-BDG | B12: Pengadilan Tinggi Bandung | K12: MA-04.01 | L12: MA-04 Kepatuhan Putusan | M12: Putusan perkara perdata dieksekusi | N12: Persentase putusan perdata dieksekusi | P12: 11 | Q12: Kegiatan Pengendalian — Penetapan dan reviu atas indikator kinerja
A13: PA-JKT | B13: Pengadilan Agama Jakarta Pusat | K13: MA-04.02 | L13: MA-04 Kepatuhan Putusan | M13: Putusan perkara TUN dieksekusi | N13: Persentase putusan TUN dieksekusi | P13: 12 | Q13: Kegiatan Pengendalian — Pemisahan fungsi
K14: MA-05.01 | L14: MA-05 Pembinaan SDM | M14: Pengadaan dan Rekrutmen Tenaga | N14: Jumlah tenaga rekrut | P14: 13 | Q14: Kegiatan Pengendalian — Otorisasi atas transaksi
K15: MA-05.02 | L15: MA-05 Pembinaan SDM | M15: Pembinaan dan Pelatihan Tenaga Teknis | N15: Jumlah peserta diklat teknis | P15: 14 | Q15: Kegiatan Pengendalian — Pencatatan yang akurat dan tepat waktu
K16: MA-05.03 | L16: MA-05 Pembinaan SDM | M16: Pembinaan dan Pelatihan Tenaga Non Teknis | N16: Jumlah peserta diklat non teknis | P16: 15 | Q16: Kegiatan Pengendalian — Pembatasan akses atas sumber daya
K17: MA-05.04 | L17: MA-05 Pembinaan SDM | M17: Promosi dan Mutasi | N17: Jumlah SK promosi/mutasi | P17: 16 | Q17: Kegiatan Pengendalian — Akuntabilitas terhadap sumber daya
K18: MA-06.01 | L18: MA-06 Pengembangan Kebijakan | M18: Pengembangan Peraturan Perundang-Undangan | N18: Jumlah peraturan diterbitkan | P18: 17 | Q18: Kegiatan Pengendalian — Dokumentasi atas sistem pengendalian intern
K19: MA-06.02 | L19: MA-06 Pengembangan Kebijakan | M19: Pengembangan SK Ketua MA | N19: Jumlah SKKMA diterbitkan | P19: 18 | Q19: Informasi dan Komunikasi — Informasi yang relevan
K20: MA-06.03 | L20: MA-06 Pengembangan Kebijakan | M20: Pengembangan Keputusan Pejabat Eselon I | N20: Jumlah SK Eselon I | P20: 19 | Q20: Informasi dan Komunikasi — Komunikasi yang efektif
K21: MA-07.01 | L21: MA-07 Pengawasan Kinerja | M21: Pengembangan Sistem Pengawasan Berbasis TI | N21: Persentase sistem pengawasan TI terimplementasi | P21: 20 | Q21: Pemantauan — Pemantauan berkelanjutan
K22: MA-07.02 | L22: MA-07 Pengawasan Kinerja | M22: Implementasi Pengawasan Internal | N22: Jumlah laporan pengawasan internal | P22: 21 | Q22: Pemantauan — Evaluasi terpisah
K23: MA-07.03 | L23: MA-07 Pengawasan Kinerja | M23: Implementasi Pengawasan Eksternal | N23: Jumlah tindak lanjut pengawasan eksternal | P23: 22 | Q23: Pemantauan — Tindak lanjut rekomendasi
K24: MA-08.01 | L24: MA-08 Administrasi | M24: Rencana Program dan Penganggaran | N24: Persentase realisasi anggaran
K25: MA-08.02 | L25: MA-08 Administrasi | M25: Pengelolaan Organisasi dan Tata Laksana | N25: Jumlah dokumen tata laksana
K26: MA-08.03 | L26: MA-08 Administrasi | M26: Pengelolaan Sarana dan Prasarana | N26: Persentase sapras terpelihara
K27: MA-08.04 | L27: MA-08 Administrasi | M27: Layanan Kehumasan dan Informasi Publik | N27: Indeks kepuasan informasi publik
K28: MA-09.01 | L28: MA-09 Teknologi Informasi | M28: Perencanaan Pembangunan TI | N28: Jumlah dokumen perencanaan TI
K29: MA-09.02 | L29: MA-09 Teknologi Informasi | M29: Pembangunan dan Pengembangan TI | N29: Jumlah sistem TI dikembangkan
K30: MA-09.03 | L30: MA-09 Teknologi Informasi | M30: Pengelolaan dan Pemeliharaan TI | N30: Persentase uptime sistem TI
K31: MA-10.01 | L31: MA-10 Koordinasi K/L | M31: Rencana Program Sinergitas Antar Instansi | N31: Jumlah MoU/PKS aktif
K32: MA-10.02 | L32: MA-10 Koordinasi K/L | M32: Pertukaran Data Peningkatan Layanan Peradilan | N32: Jumlah sistem data terintegrasi

Sheet KONTEKS
B1: [1] PENETAPAN KONTEKS
B3: A. IDENTITAS KONTEKS
B4: Unit Kerja
B5: Kode Unit | C5: =IFERROR(XLOOKUP(C4,MASTER!$B:$B,MASTER!$A:$A),"")
B6: Tahun Penerapan
B7: Periode Mulai
B8: Periode Selesai
B10: B. PEJABAT PENANGGUNG JAWAB
B11: Nama Pemilik Risiko
B12: Jabatan Pemilik Risiko
B13: Nama Pengelola Risiko
B14: Jabatan Pengelola Risiko
B16: C. SASARAN STRATEGIS (maks. 5)
B17: No | C17: Uraian Sasaran Strategis | D17: Indikator Kinerja | E17: Target
B18: 1
B19: 2
B20: 3
B21: 4
B22: 5
B24: D. PROSES BISNIS UTAMA (maks. 5)
B25: No | C25: Kode Proses (pilih) | D25: Sub Proses (otomatis) | E25: Indikator Proses (otomatis)
B26: 1 | D26: =IFERROR(XLOOKUP(C26,MASTER!$K:$K,MASTER!$M:$M),"") | E26: =IFERROR(XLOOKUP(C26,MASTER!$K:$K,MASTER!$N:$N),"")
B27: 2 | D27: =IFERROR(XLOOKUP(C27,MASTER!$K:$K,MASTER!$M:$M),"") | E27: =IFERROR(XLOOKUP(C27,MASTER!$K:$K,MASTER!$N:$N),"")
B28: 3 | D28: =IFERROR(XLOOKUP(C28,MASTER!$K:$K,MASTER!$M:$M),"") | E28: =IFERROR(XLOOKUP(C28,MASTER!$K:$K,MASTER!$N:$N),"")
B29: 4 | D29: =IFERROR(XLOOKUP(C29,MASTER!$K:$K,MASTER!$M:$M),"") | E29: =IFERROR(XLOOKUP(C29,MASTER!$K:$K,MASTER!$N:$N),"")
B30: 5 | D30: =IFERROR(XLOOKUP(C30,MASTER!$K:$K,MASTER!$M:$M),"") | E30: =IFERROR(XLOOKUP(C30,MASTER!$K:$K,MASTER!$N:$N),"")
B32: E. PEMANGKU KEPENTINGAN

Sheet SELERA_RISIKO
B1: [2] PENETAPAN SELERA RISIKO
B2: Isi threshold 1–5 untuk setiap kategori. Risiko dengan level residual DI ATAS threshold = PRIORITAS.
B4: No | C4: Kategori Risiko | D4: Threshold (1–5) | E4: Makna Threshold
B5: 1 | C5: Strategis | D5: 3 | E5: =IFERROR(INDEX({"1 = Nol toleransi — sekecil apapun harus dimitigasi","2 = Toleransi sangat rendah — risiko rendah pun perlu perhatian","3 = Toleransi sedang — risiko di atas sedang harus dimitigasi","4 = Toleransi tinggi — hanya risiko sangat tinggi yang diprioritaskan","5 = Risiko apapun dapat diterima (tidak disarankan)"},D5),"")
B6: 2 | C6: Kebijakan | D6: 3 | E6: =IFERROR(INDEX({"1 = Nol toleransi — sekecil apapun harus dimitigasi","2 = Toleransi sangat rendah — risiko rendah pun perlu perhatian","3 = Toleransi sedang — risiko di atas sedang harus dimitigasi","4 = Toleransi tinggi — hanya risiko sangat tinggi yang diprioritaskan","5 = Risiko apapun dapat diterima (tidak disarankan)"},D6),"")
B7: 3 | C7: Kecurangan | D7: 3 | E7: =IFERROR(INDEX({"1 = Nol toleransi — sekecil apapun harus dimitigasi","2 = Toleransi sangat rendah — risiko rendah pun perlu perhatian","3 = Toleransi sedang — risiko di atas sedang harus dimitigasi","4 = Toleransi tinggi — hanya risiko sangat tinggi yang diprioritaskan","5 = Risiko apapun dapat diterima (tidak disarankan)"},D7),"")
B8: 4 | C8: Bencana | D8: 3 | E8: =IFERROR(INDEX({"1 = Nol toleransi — sekecil apapun harus dimitigasi","2 = Toleransi sangat rendah — risiko rendah pun perlu perhatian","3 = Toleransi sedang — risiko di atas sedang harus dimitigasi","4 = Toleransi tinggi — hanya risiko sangat tinggi yang diprioritaskan","5 = Risiko apapun dapat diterima (tidak disarankan)"},D8),"")
B9: 5 | C9: Kepatuhan | D9: 3 | E9: =IFERROR(INDEX({"1 = Nol toleransi — sekecil apapun harus dimitigasi","2 = Toleransi sangat rendah — risiko rendah pun perlu perhatian","3 = Toleransi sedang — risiko di atas sedang harus dimitigasi","4 = Toleransi tinggi — hanya risiko sangat tinggi yang diprioritaskan","5 = Risiko apapun dapat diterima (tidak disarankan)"},D9),"")
B10: 6 | C10: Operasional | D10: 3 | E10: =IFERROR(INDEX({"1 = Nol toleransi — sekecil apapun harus dimitigasi","2 = Toleransi sangat rendah — risiko rendah pun perlu perhatian","3 = Toleransi sedang — risiko di atas sedang harus dimitigasi","4 = Toleransi tinggi — hanya risiko sangat tinggi yang diprioritaskan","5 = Risiko apapun dapat diterima (tidak disarankan)"},D10),"")
B11: 7 | C11: Kemitraan | D11: 3 | E11: =IFERROR(INDEX({"1 = Nol toleransi — sekecil apapun harus dimitigasi","2 = Toleransi sangat rendah — risiko rendah pun perlu perhatian","3 = Toleransi sedang — risiko di atas sedang harus dimitigasi","4 = Toleransi tinggi — hanya risiko sangat tinggi yang diprioritaskan","5 = Risiko apapun dapat diterima (tidak disarankan)"},D11),"")

Sheet IDENTIFIKASI
A1: [3] IDENTIFIKASI RISIKO — Format Lampiran 5
A2: ID | B2: Kode Risiko | C2: Kode Proses Bisnis | D2: Sub Proses | E2: Indikator Konteks | F2: Sasaran Strategis | G2: Pernyataan Risiko | H2: Kategori Risiko | I2: Dampak Potensial | J2: Metode SPIP | K2: Sumber Risiko | L2: Nama Pemilik Risiko | M2: Jabatan Pemilik Risiko | N2: Nama Pengelola Risiko | O2: Jabatan Pengelola Risiko | P2: Keterangan
A3: =IF(G3<>"",ROW()-2,"") | B3: =IF(G3="","",IFERROR(XLOOKUP(KONTEKS!C5,KONTEKS!C5,KONTEKS!C5,"?"),"?")&"."&IFERROR(XLOOKUP(H3,MASTER!$E:$E,MASTER!$F:$F),"?")&"."&TEXT(COUNTIFS($H$3:H3,H3,$G$3:G3,"<>"),"000") | D3: =IFERROR(XLOOKUP(C3,MASTER!$K:$K,MASTER!$M:$M),"") | E3: =IFERROR(XLOOKUP(C3,MASTER!$K:$K,MASTER!$N:$N),"")
A4: =IF(G4<>"",ROW()-2,"") | B4: =IF(G4="","",IFERROR(XLOOKUP(KONTEKS!C5,KONTEKS!C5,KONTEKS!C5,"?"),"?")&"."&IFERROR(XLOOKUP(H4,MASTER!$E:$E,MASTER!$F:$F),"?")&"."&TEXT(COUNTIFS($H$3:H4,H4,$G$3:G4,"<>"),"000") | D4: =IFERROR(XLOOKUP(C4,MASTER!$K:$K,MASTER!$M:$M),"") | E4: =IFERROR(XLOOKUP(C4,MASTER!$K:$K,MASTER!$N:$N),"")
A5: =IF(G5<>"",ROW()-2,"") | B5: =IF(G5="","",IFERROR(XLOOKUP(KONTEKS!C5,KONTEKS!C5,KONTEKS!C5,"?"),"?")&"."&IFERROR(XLOOKUP(H5,MASTER!$E:$E,MASTER!$F:$F),"?")&"."&TEXT(COUNTIFS($H$3:H5,H5,$G$3:G5,"<>"),"000") | D5: =IFERROR(XLOOKUP(C5,MASTER!$K:$K,MASTER!$M:$M),"") | E5: =IFERROR(XLOOKUP(C5,MASTER!$K:$K,MASTER!$N:$N),"")
A6: =IF(G6<>"",ROW()-2,"") | B6: =IF(G6="","",IFERROR(XLOOKUP(KONTEKS!C5,KONTEKS!C5,KONTEKS!C5,"?"),"?")&"."&IFERROR(XLOOKUP(H6,MASTER!$E:$E,MASTER!$F:$F),"?")&"."&TEXT(COUNTIFS($H$3:H6,H6,$G$3:G6,"<>"),"000") | D6: =IFERROR(XLOOKUP(C6,MASTER!$K:$K,MASTER!$M:$M),"") | E6: =IFERROR(XLOOKUP(C6,MASTER!$K:$K,MASTER!$N:$N),"")
A7: =IF(G7<>"",ROW()-2,"") | B7: =IF(G7="","",IFERROR(XLOOKUP(KONTEKS!C5,KONTEKS!C5,KONTEKS!C5,"?"),"?")&"."&IFERROR(XLOOKUP(H7,MASTER!$E:$E,MASTER!$F:$F),"?")&"."&TEXT(COUNTIFS($H$3:H7,H7,$G$3:G7,"<>"),"000") | D7: =IFERROR(XLOOKUP(C7,MASTER!$K:$K,MASTER!$M:$M),"") | E7: =IFERROR(XLOOKUP(C7,MASTER!$K:$K,MASTER!$N:$N),"")
A8: =IF(G8<>"",ROW()-2,"") | B8: =IF(G8="","",IFERROR(XLOOKUP(KONTEKS!C5,KONTEKS!C5,KONTEKS!C5,"?"),"?")&"."&IFERROR(XLOOKUP(H8,MASTER!$E:$E,MASTER!$F:$F),"?")&"."&TEXT(COUNTIFS($H$3:H8,H8,$G$3:G8,"<>"),"000") | D8: =IFERROR(XLOOKUP(C8,MASTER!$K:$K,MASTER!$M:$M),"") | E8: =IFERROR(XLOOKUP(C8,MASTER!$K:$K,MASTER!$N:$N),"")
A9: =IF(G9<>"",ROW()-2,"") | B9: =IF(G9="","",IFERROR(XLOOKUP(KONTEKS!C5,KONTEKS!C5,KONTEKS!C5,"?"),"?")&"."&IFERROR(XLOOKUP(H9,MASTER!$E:$E,MASTER!$F:$F),"?")&"."&TEXT(COUNTIFS($H$3:H9,H9,$G$3:G9,"<>"),"000") | D9: =IFERROR(XLOOKUP(C9,MASTER!$K:$K,MASTER!$M:$M),"") | E9: =IFERROR(XLOOKUP(C9,MASTER!$K:$K,MASTER!$N:$N),"")
A10: =IF(G10<>"",ROW()-2,"") | B10: =IF(G10="","",IFERROR(XLOOKUP(KONTEKS!C5,KONTEKS!C5,KONTEKS!C5,"?"),"?")&"."&IFERROR(XLOOKUP(H10,MASTER!$E:$E,MASTER!$F:$F),"?")&"."&TEXT(COUNTIFS($H$3:H10,H10,$G$3:G10,"<>"),"000") | D10: =IFERROR(XLOOKUP(C10,MASTER!$K:$K,MASTER!$M:$M),"") | E10: =IFERROR(XLOOKUP(C10,MASTER!$K:$K,MASTER!$N:$N),"")
A11: =IF(G11<>"",ROW()-2,"") | B11: =IF(G11="","",IFERROR(XLOOKUP(KONTEKS!C5,KONTEKS!C5,KONTEKS!C5,"?"),"?")&"."&IFERROR(XLOOKUP(H11,MASTER!$E:$E,MASTER!$F:$F),"?")&"."&TEXT(COUNTIFS($H$3:H11,H11,$G$3:G11,"<>"),"000") | D11: =IFERROR(XLOOKUP(C11,MASTER!$K:$K,MASTER!$M:$M),"") | E11: =IFERROR(XLOOKUP(C11,MASTER!$K:$K,MASTER!$N:$N),"")
A12: =IF(G12<>"",ROW()-2,"") | B12: =IF(G12="","",IFERROR(XLOOKUP(KONTEKS!C5,KONTEKS!C5,KONTEKS!C5,"?"),"?")&"."&IFERROR(XLOOKUP(H12,MASTER!$E:$E,MASTER!$F:$F),"?")&"."&TEXT(COUNTIFS($H$3:H12,H12,$G$3:G12,"<>"),"000") | D12: =IFERROR(XLOOKUP(C12,MASTER!$K:$K,MASTER!$M:$M),"") | E12: =IFERROR(XLOOKUP(C12,MASTER!$K:$K,MASTER!$N:$N),"")
A13: =IF(G13<>"",ROW()-2,"") | B13: =IF(G13="","",IFERROR(XLOOKUP(KONTEKS!C5,KONTEKS!C5,KONTEKS!C5,"?"),"?")&"."&IFERROR(XLOOKUP(H13,MASTER!$E:$E,MASTER!$F:$F),"?")&"."&TEXT(COUNTIFS($H$3:H13,H13,$G$3:G13,"<>"),"000") | D13: =IFERROR(XLOOKUP(C13,MASTER!$K:$K,MASTER!$M:$M),"") | E13: =IFERROR(XLOOKUP(C13,MASTER!$K:$K,MASTER!$N:$N),"")
A14: =IF(G14<>"",ROW()-2,"") | B14: =IF(G14="","",IFERROR(XLOOKUP(KONTEKS!C5,KONTEKS!C5,KONTEKS!C5,"?"),"?")&"."&IFERROR(XLOOKUP(H14,MASTER!$E:$E,MASTER!$F:$F),"?")&"."&TEXT(COUNTIFS($H$3:H14,H14,$G$3:G14,"<>"),"000") | D14: =IFERROR(XLOOKUP(C14,MASTER!$K:$K,MASTER!$M:$M),"") | E14: =IFERROR(XLOOKUP(C14,MASTER!$K:$K,MASTER!$N:$N),"")
A15: =IF(G15<>"",ROW()-2,"") | B15: =IF(G15="","",IFERROR(XLOOKUP(KONTEKS!C5,KONTEKS!C5,KONTEKS!C5,"?"),"?")&"."&IFERROR(XLOOKUP(H15,MASTER!$E:$E,MASTER!$F:$F),"?")&"."&TEXT(COUNTIFS($H$3:H15,H15,$G$3:G15,"<>"),"000") | D15: =IFERROR(XLOOKUP(C15,MASTER!$K:$K,MASTER!$M:$M),"") | E15: =IFERROR(XLOOKUP(C15,MASTER!$K:$K,MASTER!$N:$N),"")
A16: =IF(G16<>"",ROW()-2,"") | B16: =IF(G16="","",IFERROR(XLOOKUP(KONTEKS!C5,KONTEKS!C5,KONTEKS!C5,"?"),"?")&"."&IFERROR(XLOOKUP(H16,MASTER!$E:$E,MASTER!$F:$F),"?")&"."&TEXT(COUNTIFS($H$3:H16,H16,$G$3:G16,"<>"),"000") | D16: =IFERROR(XLOOKUP(C16,MASTER!$K:$K,MASTER!$M:$M),"") | E16: =IFERROR(XLOOKUP(C16,MASTER!$K:$K,MASTER!$N:$N),"")
A17: =IF(G17<>"",ROW()-2,"") | B17: =IF(G17="","",IFERROR(XLOOKUP(KONTEKS!C5,KONTEKS!C5,KONTEKS!C5,"?"),"?")&"."&IFERROR(XLOOKUP(H17,MASTER!$E:$E,MASTER!$F:$F),"?")&"."&TEXT(COUNTIFS($H$3:H17,H17,$G$3:G17,"<>"),"000") | D17: =IFERROR(XLOOKUP(C17,MASTER!$K:$K,MASTER!$M:$M),"") | E17: =IFERROR(XLOOKUP(C17,MASTER!$K:$K,MASTER!$N:$N),"")
A18: =IF(G18<>"",ROW()-2,"") | B18: =IF(G18="","",IFERROR(XLOOKUP(KONTEKS!C5,KONTEKS!C5,KONTEKS!C5,"?"),"?")&"."&IFERROR(XLOOKUP(H18,MASTER!$E:$E,MASTER!$F:$F),"?")&"."&TEXT(COUNTIFS($H$3:H18,H18,$G$3:G18,"<>"),"000") | D18: =IFERROR(XLOOKUP(C18,MASTER!$K:$K,MASTER!$M:$M),"") | E18: =IFERROR(XLOOKUP(C18,MASTER!$K:$K,MASTER!$N:$N),"")
A19: =IF(G19<>"",ROW()-2,"") | B19: =IF(G19="","",IFERROR(XLOOKUP(KONTEKS!C5,KONTEKS!C5,KONTEKS!C5,"?"),"?")&"."&IFERROR(XLOOKUP(H19,MASTER!$E:$E,MASTER!$F:$F),"?")&"."&TEXT(COUNTIFS($H$3:H19,H19,$G$3:G19,"<>"),"000") | D19: =IFERROR(XLOOKUP(C19,MASTER!$K:$K,MASTER!$M:$M),"") | E19: =IFERROR(XLOOKUP(C19,MASTER!$K:$K,MASTER!$N:$N),"")
A20: =IF(G20<>"",ROW()-2,"") | B20: =IF(G20="","",IFERROR(XLOOKUP(KONTEKS!C5,KONTEKS!C5,KONTEKS!C5,"?"),"?")&"."&IFERROR(XLOOKUP(H20,MASTER!$E:$E,MASTER!$F:$F),"?")&"."&TEXT(COUNTIFS($H$3:H20,H20,$G$3:G20,"<>"),"000") | D20: =IFERROR(XLOOKUP(C20,MASTER!$K:$K,MASTER!$M:$M),"") | E20: =IFERROR(XLOOKUP(C20,MASTER!$K:$K,MASTER!$N:$N),"")
A21: =IF(G21<>"",ROW()-2,"") | B21: =IF(G21="","",IFERROR(XLOOKUP(KONTEKS!C5,KONTEKS!C5,KONTEKS!C5,"?"),"?")&"."&IFERROR(XLOOKUP(H21,MASTER!$E:$E,MASTER!$F:$F),"?")&"."&TEXT(COUNTIFS($H$3:H21,H21,$G$3:G21,"<>"),"000") | D21: =IFERROR(XLOOKUP(C21,MASTER!$K:$K,MASTER!$M:$M),"") | E21: =IFERROR(XLOOKUP(C21,MASTER!$K:$K,MASTER!$N:$N),"")
A22: =IF(G22<>"",ROW()-2,"") | B22: =IF(G22="","",IFERROR(XLOOKUP(KONTEKS!C5,KONTEKS!C5,KONTEKS!C5,"?"),"?")&"."&IFERROR(XLOOKUP(H22,MASTER!$E:$E,MASTER!$F:$F),"?")&"."&TEXT(COUNTIFS($H$3:H22,H22,$G$3:G22,"<>"),"000") | D22: =IFERROR(XLOOKUP(C22,MASTER!$K:$K,MASTER!$M:$M),"") | E22: =IFERROR(XLOOKUP(C22,MASTER!$K:$K,MASTER!$N:$N),"")
A23: =IF(G23<>"",ROW()-2,"") | B23: =IF(G23="","",IFERROR(XLOOKUP(KONTEKS!C5,KONTEKS!C5,KONTEKS!C5,"?"),"?")&"."&IFERROR(XLOOKUP(H23,MASTER!$E:$E,MASTER!$F:$F),"?")&"."&TEXT(COUNTIFS($H$3:H23,H23,$G$3:G23,"<>"),"000") | D23: =IFERROR(XLOOKUP(C23,MASTER!$K:$K,MASTER!$M:$M),"") | E23: =IFERROR(XLOOKUP(C23,MASTER!$K:$K,MASTER!$N:$N),"")
A24: =IF(G24<>"",ROW()-2,"") | B24: =IF(G24="","",IFERROR(XLOOKUP(KONTEKS!C5,KONTEKS!C5,KONTEKS!C5,"?"),"?")&"."&IFERROR(XLOOKUP(H24,MASTER!$E:$E,MASTER!$F:$F),"?")&"."&TEXT(COUNTIFS($H$3:H24,H24,$G$3:G24,"<>"),"000") | D24: =IFERROR(XLOOKUP(C24,MASTER!$K:$K,MASTER!$M:$M),"") | E24: =IFERROR(XLOOKUP(C24,MASTER!$K:$K,MASTER!$N:$N),"")
A25: =IF(G25<>"",ROW()-2,"") | B25: =IF(G25="","",IFERROR(XLOOKUP(KONTEKS!C5,KONTEKS!C5,KONTEKS!C5,"?"),"?")&"."&IFERROR(XLOOKUP(H25,MASTER!$E:$E,MASTER!$F:$F),"?")&"."&TEXT(COUNTIFS($H$3:H25,H25,$G$3:G25,"<>"),"000") | D25: =IFERROR(XLOOKUP(C25,MASTER!$K:$K,MASTER!$M:$M),"") | E25: =IFERROR(XLOOKUP(C25,MASTER!$K:$K,MASTER!$N:$N),"")
A26: =IF(G26<>"",ROW()-2,"") | B26: =IF(G26="","",IFERROR(XLOOKUP(KONTEKS!C5,KONTEKS!C5,KONTEKS!C5,"?"),"?")&"."&IFERROR(XLOOKUP(H26,MASTER!$E:$E,MASTER!$F:$F),"?")&"."&TEXT(COUNTIFS($H$3:H26,H26,$G$3:G26,"<>"),"000") | D26: =IFERROR(XLOOKUP(C26,MASTER!$K:$K,MASTER!$M:$M),"") | E26: =IFERROR(XLOOKUP(C26,MASTER!$K:$K,MASTER!$N:$N),"")
A27: =IF(G27<>"",ROW()-2,"") | B27: =IF(G27="","",IFERROR(XLOOKUP(KONTEKS!C5,KONTEKS!C5,KONTEKS!C5,"?"),"?")&"."&IFERROR(XLOOKUP(H27,MASTER!$E:$E,MASTER!$F:$F),"?")&"."&TEXT(COUNTIFS($H$3:H27,H27,$G$3:G27,"<>"),"000") | D27: =IFERROR(XLOOKUP(C27,MASTER!$K:$K,MASTER!$M:$M),"") | E27: =IFERROR(XLOOKUP(C27,MASTER!$K:$K,MASTER!$N:$N),"")
A28: =IF(G28<>"",ROW()-2,"") | B28: =IF(G28="","",IFERROR(XLOOKUP(KONTEKS!C5,KONTEKS!C5,KONTEKS!C5,"?"),"?")&"."&IFERROR(XLOOKUP(H28,MASTER!$E:$E,MASTER!$F:$F),"?")&"."&TEXT(COUNTIFS($H$3:H28,H28,$G$3:G28,"<>"),"000") | D28: =IFERROR(XLOOKUP(C28,MASTER!$K:$K,MASTER!$M:$M),"") | E28: =IFERROR(XLOOKUP(C28,MASTER!$K:$K,MASTER!$N:$N),"")
A29: =IF(G29<>"",ROW()-2,"") | B29: =IF(G29="","",IFERROR(XLOOKUP(KONTEKS!C5,KONTEKS!C5,KONTEKS!C5,"?"),"?")&"."&IFERROR(XLOOKUP(H29,MASTER!$E:$E,MASTER!$F:$F),"?")&"."&TEXT(COUNTIFS($H$3:H29,H29,$G$3:G29,"<>"),"000") | D29: =IFERROR(XLOOKUP(C29,MASTER!$K:$K,MASTER!$M:$M),"") | E29: =IFERROR(XLOOKUP(C29,MASTER!$K:$K,MASTER!$N:$N),"")
A30: =IF(G30<>"",ROW()-2,"") | B30: =IF(G30="","",IFERROR(XLOOKUP(KONTEKS!C5,KONTEKS!C5,KONTEKS!C5,"?"),"?")&"."&IFERROR(XLOOKUP(H30,MASTER!$E:$E,MASTER!$F:$F),"?")&"."&TEXT(COUNTIFS($H$3:H30,H30,$G$3:G30,"<>"),"000") | D30: =IFERROR(XLOOKUP(C30,MASTER!$K:$K,MASTER!$M:$M),"") | E30: =IFERROR(XLOOKUP(C30,MASTER!$K:$K,MASTER!$N:$N),"")
A31: =IF(G31<>"",ROW()-2,"") | B31: =IF(G31="","",IFERROR(XLOOKUP(KONTEKS!C5,KONTEKS!C5,KONTEKS!C5,"?"),"?")&"."&IFERROR(XLOOKUP(H31,MASTER!$E:$E,MASTER!$F:$F),"?")&"."&TEXT(COUNTIFS($H$3:H31,H31,$G$3:G31,"<>"),"000") | D31: =IFERROR(XLOOKUP(C31,MASTER!$K:$K,MASTER!$M:$M),"") | E31: =IFERROR(XLOOKUP(C31,MASTER!$K:$K,MASTER!$N:$N),"")
A32: =IF(G32<>"",ROW()-2,"") | B32: =IF(G32="","",IFERROR(XLOOKUP(KONTEKS!C5,KONTEKS!C5,KONTEKS!C5,"?"),"?")&"."&IFERROR(XLOOKUP(H32,MASTER!$E:$E,MASTER!$F:$F),"?")&"."&TEXT(COUNTIFS($H$3:H32,H32,$G$3:G32,"<>"),"000") | D32: =IFERROR(XLOOKUP(C32,MASTER!$K:$K,MASTER!$M:$M),"") | E32: =IFERROR(XLOOKUP(C32,MASTER!$K:$K,MASTER!$N:$N),"")
A33: =IF(G33<>"",ROW()-2,"") | B33: =IF(G33="","",IFERROR(XLOOKUP(KONTEKS!C5,KONTEKS!C5,KONTEKS!C5,"?"),"?")&"."&IFERROR(XLOOKUP(H33,MASTER!$E:$E,MASTER!$F:$F),"?")&"."&TEXT(COUNTIFS($H$3:H33,H33,$G$3:G33,"<>"),"000") | D33: =IFERROR(XLOOKUP(C33,MASTER!$K:$K,MASTER!$M:$M),"") | E33: =IFERROR(XLOOKUP(C33,MASTER!$K:$K,MASTER!$N:$N),"")
A34: =IF(G34<>"",ROW()-2,"") | B34: =IF(G34="","",IFERROR(XLOOKUP(KONTEKS!C5,KONTEKS!C5,KONTEKS!C5,"?"),"?")&"."&IFERROR(XLOOKUP(H34,MASTER!$E:$E,MASTER!$F:$F),"?")&"."&TEXT(COUNTIFS($H$3:H34,H34,$G$3:G34,"<>"),"000") | D34: =IFERROR(XLOOKUP(C34,MASTER!$K:$K,MASTER!$M:$M),"") | E34: =IFERROR(XLOOKUP(C34,MASTER!$K:$K,MASTER!$N:$N),"")
A35: =IF(G35<>"",ROW()-2,"") | B35: =IF(G35="","",IFERROR(XLOOKUP(KONTEKS!C5,KONTEKS!C5,KONTEKS!C5,"?"),"?")&"."&IFERROR(XLOOKUP(H35,MASTER!$E:$E,MASTER!$F:$F),"?")&"."&TEXT(COUNTIFS($H$3:H35,H35,$G$3:G35,"<>"),"000") | D35: =IFERROR(XLOOKUP(C35,MASTER!$K:$K,MASTER!$M:$M),"") | E35: =IFERROR(XLOOKUP(C35,MASTER!$K:$K,MASTER!$N:$N),"")
A36: =IF(G36<>"",ROW()-2,"") | B36: =IF(G36="","",IFERROR(XLOOKUP(KONTEKS!C5,KONTEKS!C5,KONTEKS!C5,"?"),"?")&"."&IFERROR(XLOOKUP(H36,MASTER!$E:$E,MASTER!$F:$F),"?")&"."&TEXT(COUNTIFS($H$3:H36,H36,$G$3:G36,"<>"),"000") | D36: =IFERROR(XLOOKUP(C36,MASTER!$K:$K,MASTER!$M:$M),"") | E36: =IFERROR(XLOOKUP(C36,MASTER!$K:$K,MASTER!$N:$N),"")
A37: =IF(G37<>"",ROW()-2,"") | B37: =IF(G37="","",IFERROR(XLOOKUP(KONTEKS!C5,KONTEKS!C5,KONTEKS!C5,"?"),"?")&"."&IFERROR(XLOOKUP(H37,MASTER!$E:$E,MASTER!$F:$F),"?")&"."&TEXT(COUNTIFS($H$3:H37,H37,$G$3:G37,"<>"),"000") | D37: =IFERROR(XLOOKUP(C37,MASTER!$K:$K,MASTER!$M:$M),"") | E37: =IFERROR(XLOOKUP(C37,MASTER!$K:$K,MASTER!$N:$N),"")
A38: =IF(G38<>"",ROW()-2,"") | B38: =IF(G38="","",IFERROR(XLOOKUP(KONTEKS!C5,KONTEKS!C5,KONTEKS!C5,"?"),"?")&"."&IFERROR(XLOOKUP(H38,MASTER!$E:$E,MASTER!$F:$F),"?")&"."&TEXT(COUNTIFS($H$3:H38,H38,$G$3:G38,"<>"),"000") | D38: =IFERROR(XLOOKUP(C38,MASTER!$K:$K,MASTER!$M:$M),"") | E38: =IFERROR(XLOOKUP(C38,MASTER!$K:$K,MASTER!$N:$N),"")
A39: =IF(G39<>"",ROW()-2,"") | B39: =IF(G39="","",IFERROR(XLOOKUP(KONTEKS!C5,KONTEKS!C5,KONTEKS!C5,"?"),"?")&"."&IFERROR(XLOOKUP(H39,MASTER!$E:$E,MASTER!$F:$F),"?")&"."&TEXT(COUNTIFS($H$3:H39,H39,$G$3:G39,"<>"),"000") | D39: =IFERROR(XLOOKUP(C39,MASTER!$K:$K,MASTER!$M:$M),"") | E39: =IFERROR(XLOOKUP(C39,MASTER!$K:$K,MASTER!$N:$N),"")
A40: =IF(G40<>"",ROW()-2,"") | B40: =IF(G40="","",IFERROR(XLOOKUP(KONTEKS!C5,KONTEKS!C5,KONTEKS!C5,"?"),"?")&"."&IFERROR(XLOOKUP(H40,MASTER!$E:$E,MASTER!$F:$F),"?")&"."&TEXT(COUNTIFS($H$3:H40,H40,$G$3:G40,"<>"),"000") | D40: =IFERROR(XLOOKUP(C40,MASTER!$K:$K,MASTER!$M:$M),"") | E40: =IFERROR(XLOOKUP(C40,MASTER!$K:$K,MASTER!$N:$N),"")
...

Sheet PENYEBAB
A1: [4] IDENTIFIKASI PENYEBAB RISIKO (5-WHYS) — Format Lampiran 9
A2: Penyebab ID | B2: Kode Risiko (pilih ID dari [3]) | C2: Pernyataan Risiko | D2: Kat. Penyebab (5M+EX) | E2: Kode Penyebab | F2: Why 1 | G2: Why 2 | H2: Why 3 | I2: Why 4 | J2: Why 5 | K2: Akar Penyebab | L2: Kegiatan Pengendalian Eksisting | M2: Keterangan
A3: Kolom B: isi Kode Risiko (salin dari kolom B sheet [3] IDENTIFIKASI). Kolom D: pilih kategori 5M+EX dari dropdown. Kolom E: terisi otomatis.
A4: =IF(B4<>"",ROW()-3,"") | C4: =IFERROR(XLOOKUP(B4,IDENTIFIKASI!$B:$B,IDENTIFIKASI!$G:$G),"") | E4: =IF(B4="","",B4&"."&IF(D4<>"",D4,"XX")&"."&TEXT(COUNTIFS($B$4:B4,B4,$D$4:D4,D4),"00"))
A5: =IF(B5<>"",ROW()-3,"") | C5: =IFERROR(XLOOKUP(B5,IDENTIFIKASI!$B:$B,IDENTIFIKASI!$G:$G),"") | E5: =IF(B5="","",B5&"."&IF(D5<>"",D5,"XX")&"."&TEXT(COUNTIFS($B$4:B5,B5,$D$4:D5,D5),"00"))
A6: =IF(B6<>"",ROW()-3,"") | C6: =IFERROR(XLOOKUP(B6,IDENTIFIKASI!$B:$B,IDENTIFIKASI!$G:$G),"") | E6: =IF(B6="","",B6&"."&IF(D6<>"",D6,"XX")&"."&TEXT(COUNTIFS($B$4:B6,B6,$D$4:D6,D6),"00"))
A7: =IF(B7<>"",ROW()-3,"") | C7: =IFERROR(XLOOKUP(B7,IDENTIFIKASI!$B:$B,IDENTIFIKASI!$G:$G),"") | E7: =IF(B7="","",B7&"."&IF(D7<>"",D7,"XX")&"."&TEXT(COUNTIFS($B$4:B7,B7,$D$4:D7,D7),"00"))
A8: =IF(B8<>"",ROW()-3,"") | C8: =IFERROR(XLOOKUP(B8,IDENTIFIKASI!$B:$B,IDENTIFIKASI!$G:$G),"") | E8: =IF(B8="","",B8&"."&IF(D8<>"",D8,"XX")&"."&TEXT(COUNTIFS($B$4:B8,B8,$D$4:D8,D8),"00"))
A9: =IF(B9<>"",ROW()-3,"") | C9: =IFERROR(XLOOKUP(B9,IDENTIFIKASI!$B:$B,IDENTIFIKASI!$G:$G),"") | E9: =IF(B9="","",B9&"."&IF(D9<>"",D9,"XX")&"."&TEXT(COUNTIFS($B$4:B9,B9,$D$4:D9,D9),"00"))
A10: =IF(B10<>"",ROW()-3,"") | C10: =IFERROR(XLOOKUP(B10,IDENTIFIKASI!$B:$B,IDENTIFIKASI!$G:$G),"") | E10: =IF(B10="","",B10&"."&IF(D10<>"",D10,"XX")&"."&TEXT(COUNTIFS($B$4:B10,B10,$D$4:D10,D10),"00"))
A11: =IF(B11<>"",ROW()-3,"") | C11: =IFERROR(XLOOKUP(B11,IDENTIFIKASI!$B:$B,IDENTIFIKASI!$G:$G),"") | E11: =IF(B11="","",B11&"."&IF(D11<>"",D11,"XX")&"."&TEXT(COUNTIFS($B$4:B11,B11,$D$4:D11,D11),"00"))
A12: =IF(B12<>"",ROW()-3,"") | C12: =IFERROR(XLOOKUP(B12,IDENTIFIKASI!$B:$B,IDENTIFIKASI!$G:$G),"") | E12: =IF(B12="","",B12&"."&IF(D12<>"",D12,"XX")&"."&TEXT(COUNTIFS($B$4:B12,B12,$D$4:D12,D12),"00"))
A13: =IF(B13<>"",ROW()-3,"") | C13: =IFERROR(XLOOKUP(B13,IDENTIFIKASI!$B:$B,IDENTIFIKASI!$G:$G),"") | E13: =IF(B13="","",B13&"."&IF(D13<>"",D13,"XX")&"."&TEXT(COUNTIFS($B$4:B13,B13,$D$4:D13,D13),"00"))
A14: =IF(B14<>"",ROW()-3,"") | C14: =IFERROR(XLOOKUP(B14,IDENTIFIKASI!$B:$B,IDENTIFIKASI!$G:$G),"") | E14: =IF(B14="","",B14&"."&IF(D14<>"",D14,"XX")&"."&TEXT(COUNTIFS($B$4:B14,B14,$D$4:D14,D14),"00"))
A15: =IF(B15<>"",ROW()-3,"") | C15: =IFERROR(XLOOKUP(B15,IDENTIFIKASI!$B:$B,IDENTIFIKASI!$G:$G),"") | E15: =IF(B15="","",B15&"."&IF(D15<>"",D15,"XX")&"."&TEXT(COUNTIFS($B$4:B15,B15,$D$4:D15,D15),"00"))
... A153: =IF(B153<>"",ROW()-3,"") | C153: =IFERROR(XLOOKUP(B153,IDENTIFIKASI!$B:$B,IDENTIFIKASI!$G:$G),"") | E153: =IF(B153="","",B153&"."&IF(D153<>"",D153,"XX")&"."&TEXT(COUNTIFS($B$4:B153,B153,$D$4:D153,D153),"00"))

Sheet ANALISIS
A1: [5] ANALISIS RISIKO — Matriks 5×5 Kemungkinan × Dampak
A2: Kode Risiko (dari [3]) | B2: Pernyataan Risiko | C2: Kategori | D2: Kemungkinan Inheren (1–5) | E2: Dampak Inheren (1–5) | F2: Besaran Inheren | G2: Level Inheren | H2: Label Inheren | I2: Ada Pengendalian? | J2: Pengendalian Eksisting | K2: Efektivitas Pengendalian | L2: Kecukupan Pengendalian | M2: Kemungkinan Residual (1–5) | N2: Dampak Residual (1–5) | O2: Besaran Residual | P2: Level Residual | Q2: Label Residual | R2: Threshold (dari [2]) | S2: Di Atas Selera? | T2: Keterangan
B3: =IFERROR(XLOOKUP(A3,IDENTIFIKASI!$B:$B,IDENTIFIKASI!$G:$G),"") | C3: =IFERROR(XLOOKUP(A3,IDENTIFIKASI!$B:$B,IDENTIFIKASI!$H:$H),"") | F3: =IF(AND(D3<>"",E3<>""),D3*E3,"") | G3: =IF(F3="","",IFS(F3>=20,5,F3>=16,4,F3>=11,3,F3>=6,2,F3>0,1,TRUE,"")) | H3: =IFERROR(INDEX({"","Sangat Rendah","Rendah","Sedang","Tinggi","Sangat Tinggi"},G3+1),"") | O3: =IF(A3="","",IF(AND(M3<>"",N3<>""),M3*N3,IF(AND(D3<>"",E3<>""),D3*E3,""))) | P3: =IF(O3="","",IFS(O3>=20,5,O3>=16,4,O3>=11,3,O3>=6,2,O3>0,1,TRUE,"")) | Q3: =IFERROR(INDEX({"","Sangat Rendah","Rendah","Sedang","Tinggi","Sangat Tinggi"},P3+1),"") | R3: =IFERROR(XLOOKUP(C3,SELERA_RISIKO!$C$5:$C$11,SELERA_RISIKO!$D$5:$D$11),"") | S3: =IF(AND(P3<>"",R3<>""),IF(P3>R3,"YA ⚠","tidak"),"")
B4: =IFERROR(XLOOKUP(A4,IDENTIFIKASI!$B:$B,IDENTIFIKASI!$G:$G),"") | C4: =IFERROR(XLOOKUP(A4,IDENTIFIKASI!$B:$B,IDENTIFIKASI!$H:$H),"") | F4: =IF(AND(D4<>"",E4<>""),D4*E4,"") | G4: =IF(F4="","",IFS(F4>=20,5,F4>=16,4,F4>=11,3,F4>=6,2,F4>0,1,TRUE,"")) | H4: =IFERROR(INDEX({"","Sangat Rendah","Rendah","Sedang","Tinggi","Sangat Tinggi"},G4+1),"") | O4: =IF(A4="","",IF(AND(M4<>"",N4<>""),M4*N4,IF(AND(D4<>"",E4<>""),D4*E4,""))) | P4: =IF(O4="","",IFS(O4>=20,5,O4>=16,4,O4>=11,3,O4>=6,2,O4>0,1,TRUE,"")) | Q4: =IFERROR(INDEX({"","Sangat Rendah","Rendah","Sedang","Tinggi","Sangat Tinggi"},P4+1),"") | R4: =IFERROR(XLOOKUP(C4,SELERA_RISIKO!$C$5:$C$11,SELERA_RISIKO!$D$5:$D$11),"") | S4: =IF(AND(P4<>"",R4<>""),IF(P4>R4,"YA ⚠","tidak"),"")
B5: =IFERROR(XLOOKUP(A5,IDENTIFIKASI!$B:$B,IDENTIFIKASI!$G:$G),"") | C5: =IFERROR(XLOOKUP(A5,IDENTIFIKASI!$B:$B,IDENTIFIKASI!$H:$H),"") | F5: =IF(AND(D5<>"",E5<>""),D5*E5,"") | G5: =IF(F5="","",IFS(F5>=20,5,F5>=16,4,F5>=11,3,F5>=6,2,F5>0,1,TRUE,"")) | H5: =IFERROR(INDEX({"","Sangat Rendah","Rendah","Sedang","Tinggi","Sangat Tinggi"},G5+1),"") | O5: =IF(A5="","",IF(AND(M5<>"",N5<>""),M5*N5,IF(AND(D5<>"",E5<>""),D5*E5,""))) | P5: =IF(O5="","",IFS(O5>=20,5,O5>=16,4,O5>=11,3,O5>=6,2,O5>0,1,TRUE,"")) | Q5: =IFERROR(INDEX({"","Sangat Rendah","Rendah","Sedang","Tinggi","Sangat Tinggi"},P5+1),"") | R5: =IFERROR(XLOOKUP(C5,SELERA_RISIKO!$C$5:$C$11,SELERA_RISIKO!$D$5:$D$11),"") | S5: =IF(AND(P5<>"",R5<>""),IF(P5>R5,"YA ⚠","tidak"),"")
B6: =IFERROR(XLOOKUP(A6,IDENTIFIKASI!$B:$B,IDENTIFIKASI!$G:$G),"") | C6: =IFERROR(XLOOKUP(A6,IDENTIFIKASI!$B:$B,IDENTIFIKASI!$H:$H),"") | F6: =IF(AND(D6<>"",E6<>""),D6*E6,"") | G6: =IF(F6="","",IFS(F6>=20,5,F6>=16,4,F6>=11,3,F6>=6,2,F6>0,1,TRUE,"")) | H6: =IFERROR(INDEX({"","Sangat Rendah","Rendah","Sedang","Tinggi","Sangat Tinggi"},G6+1),"") | O6: =IF(A6="","",IF(AND(M6<>"",N6<>""),M6*N6,IF(AND(D6<>"",E6<>""),D6*E6,""))) | P6: =IF(O6="","",IFS(O6>=20,5,O6>=16,4,O6>=11,3,O6>=6,2,O6>0,1,TRUE,"")) | Q6: =IFERROR(INDEX({"","Sangat Rendah","Rendah","Sedang","Tinggi","Sangat Tinggi"},P6+1),"") | R6: =IFERROR(XLOOKUP(C6,SELERA_RISIKO!$C$5:$C$11,SELERA_RISIKO!$D$5:$D$11),"") | S6: =IF(AND(P6<>"",R6<>""),IF(P6>R6,"YA ⚠","tidak"),"")
B7: =IFERROR(XLOOKUP(A7,IDENTIFIKASI!$B:$B,IDENTIFIKASI!$G:$G),"") | C7: =IFERROR(XLOOKUP(A7,IDENTIFIKASI!$B:$B,IDENTIFIKASI!$H:$H),"") | F7: =IF(AND(D7<>"",E7<>""),D7*E7,"") | G7: =IF(F7="","",IFS(F7>=20,5,F7>=16,4,F7>=11,3,F7>=6,2,F7>0,1,TRUE,"")) | H7: =IFERROR(INDEX({"","Sangat Rendah","Rendah","Sedang","Tinggi","Sangat Tinggi"},G7+1),"") | O7: =IF(A7="","",IF(AND(M7<>"",N7<>""),M7*N7,IF(AND(D7<>"",E7<>""),D7*E7,""))) | P7: =IF(O7="","",IFS(O7>=20,5,O7>=16,4,O7>=11,3,O7>=6,2,O7>0,1,TRUE,"")) | Q7: =IFERROR(INDEX({"","Sangat Rendah","Rendah","Sedang","Tinggi","Sangat Tinggi"},P7+1),"") | R7: =IFERROR(XLOOKUP(C7,SELERA_RISIKO!$C$5:$C$11,SELERA_RISIKO!$D$5:$D$11),"") | S7: =IF(AND(P7<>"",R7<>""),IF(P7>R7,"YA ⚠","tidak"),"")
B8: =IFERROR(XLOOKUP(A8,IDENTIFIKASI!$B:$B,IDENTIFIKASI!$G:$G),"") | C8: =IFERROR(XLOOKUP(A8,IDENTIFIKASI!$B:$B,IDENTIFIKASI!$H:$H),"") | F8: =IF(AND(D8<>"",E8<>""),D8*E8,"") | G8: =IF(F8="","",IFS(F8>=20,5,F8>=16,4,F8>=11,3,F8>=6,2,F8>0,1,TRUE,"")) | H8: =IFERROR(INDEX({"","Sangat Rendah","Rendah","Sedang","Tinggi","Sangat Tinggi"},G8+1),"") | O8: =IF(A8="","",IF(AND(M8<>"",N8<>""),M8*N8,IF(AND(D8<>"",E8<>""),D8*E8,""))) | P8: =IF(O8="","",IFS(O8>=20,5,O8>=16,4,O8>=11,3,O8>=6,2,O8>0,1,TRUE,"")) | Q8: =IFERROR(INDEX({"","Sangat Rendah","Rendah","Sedang","Tinggi","Sangat Tinggi"},P8+1),"") | R8: =IFERROR(XLOOKUP(C8,SELERA_RISIKO!$C$5:$C$11,SELERA_RISIKO!$D$5:$D$11),"") | S8: =IF(AND(P8<>"",R8<>""),IF(P8>R8,"YA ⚠","tidak"),"")
B9: =IFERROR(XLOOKUP(A9,IDENTIFIKASI!$B:$B,IDENTIFIKASI!$G:$G),"") | C9: =IFERROR(XLOOKUP(A9,IDENTIFIKASI!$B:$B,IDENTIFIKASI!$H:$H),"") | F9: =IF(AND(D9<>"",E9<>""),D9*E9,"") | G9: =IF(F9="","",IFS(F9>=20,5,F9>=16,4,F9>=11,3,F9>=6,2,F9>0,1,TRUE,"")) | H9: =IFERROR(INDEX({"","Sangat Rendah","Rendah","Sedang","Tinggi","Sangat Tinggi"},G9+1),"") | O9: =IF(A9="","",IF(AND(M9<>"",N9<>""),M9*N9,IF(AND(D9<>"",E9<>""),D9*E9,""))) | P9: =IF(O9="","",IFS(O9>=20,5,O9>=16,4,O9>=11,3,O9>=6,2,O9>0,1,TRUE,"")) | Q9: =IFERROR(INDEX({"","Sangat Rendah","Rendah","Sedang","Tinggi","Sangat Tinggi"},P9+1),"") | R9: =IFERROR(XLOOKUP(C9,SELERA_RISIKO!$C$5:$C$11,SELERA_RISIKO!$D$5:$D$11),"") | S9: =IF(AND(P9<>"",R9<>""),IF(P9>R9,"YA ⚠","tidak"),"")
B10: =IFERROR(XLOOKUP(A10,IDENTIFIKASI!$B:$B,IDENTIFIKASI!$G:$G),"") | C10: =IFERROR(XLOOKUP(A10,IDENTIFIKASI!$B:$B,IDENTIFIKASI!$H:$H),"") | F10: =IF(AND(D10<>"",E10<>""),D10*E10,"") | G10: =IF(F10="","",IFS(F10>=20,5,F10>=16,4,F10>=11,3,F10>=6,2,F10>0,1,TRUE,"")) | H10: =IFERROR(INDEX({"","Sangat Rendah","Rendah","Sedang","Tinggi","Sangat Tinggi"},G10+1),"") | O10: =IF(A10="","",IF(AND(M10<>"",N10<>""),M10*N10,IF(AND(D10<>"",E10<>""),D10*E10,""))) | P10: =IF(O10="","",IFS(O10>=20,5,O10>=16,4,O10>=11,3,O10>=6,2,O10>0,1,TRUE,"")) | Q10: =IFERROR(INDEX({"","Sangat Rendah","Rendah","Sedang","Tinggi","Sangat Tinggi"},P10+1),"") | R10: =IFERROR(XLOOKUP(C10,SELERA_RISIKO!$C$5:$C$11,SELERA_RISIKO!$D$5:$D$11),"") | S10: =IF(AND(P10<>"",R10<>""),IF(P10>R10,"YA ⚠","tidak"),"")
B11: =IFERROR(XLOOKUP(A11,IDENTIFIKASI!$B:$B,IDENTIFIKASI!$G:$G),"") | C11: =IFERROR(XLOOKUP(A11,IDENTIFIKASI!$B:$B,IDENTIFIKASI!$H:$H),"") | F11: =IF(AND(D11<>"",E11<>""),D11*E11,"") | G11: =IF(F11="","",IFS(F11>=20,5,F11>=16,4,F11>=11,3,F11>=6,2,F11>0,1,TRUE,"")) | H11: =IFERROR(INDEX({"","Sangat Rendah","Rendah","Sedang","Tinggi","Sangat Tinggi"},G11+1),"") | O11: =IF(A11="","",IF(AND(M11<>"",N11<>""),M11*N11,IF(AND(D11<>"",E11<>""),D11*E11,""))) | P11: =IF(O11="","",IFS(O11>=20,5,O11>=16,4,O11>=11,3,O11>=6,2,O11>0,1,TRUE,"")) | Q11: =IFERROR(INDEX({"","Sangat Rendah","Rendah","Sedang","Tinggi","Sangat Tinggi"},P11+1),"") | R11: =IFERROR(XLOOKUP(C11,SELERA_RISIKO!$C$5:$C$11,SELERA_RISIKO!$D$5:$D$11),"") | S11: =IF(AND(P11<>"",R11<>""),IF(P11>R11,"YA ⚠","tidak"),"")
B12: =IFERROR(XLOOKUP(A12,IDENTIFIKASI!$B:$B,IDENTIFIKASI!$G:$G),"") | C12: =IFERROR(XLOOKUP(A12,IDENTIFIKASI!$B:$B,IDENTIFIKASI!$H:$H),"") | F12: =IF(AND(D12<>"",E12<>""),D12*E12,"") | G12: =IF(F12="","",IFS(F12>=20,5,F12>=16,4,F12>=11,3,F12>=6,2,F12>0,1,TRUE,"")) | H12: =IFERROR(INDEX({"","Sangat Rendah","Rendah","Sedang","Tinggi","Sangat Tinggi"},G12+1),"") | O12: =IF(A12="","",IF(AND(M12<>"",N12<>""),M12*N12,IF(AND(D12<>"",E12<>""),D12*E12,""))) | P12: =IF(O12="","",IFS(O12>=20,5,O12>=16,4,O12>=11,3,O12>=6,2,O12>0,1,TRUE,"")) | Q12: =IFERROR(INDEX({"","Sangat Rendah","Rendah","Sedang","Tinggi","Sangat Tinggi"},P12+1),"") | R12: =IFERROR(XLOOKUP(C12,SELERA_RISIKO!$C$5:$C$11,SELERA_RISIKO!$D$5:$D$11),"") | S12: =IF(AND(P12<>"",R12<>""),IF(P12>R12,"YA ⚠","tidak"),"")
B13: =IFERROR(XLOOKUP(A13,IDENTIFIKASI!$B:$B,IDENTIFIKASI!$G:$G),"") | C13: =IFERROR(XLOOKUP(A13,IDENTIFIKASI!$B:$B,IDENTIFIKASI!$H:$H),"") | F13: =IF(AND(D13<>"",E13<>""),D13*E13,"") | G13: =IF(F13="","",IFS(F13>=20,5,F13>=16,4,F13>=11,3,F13>=6,2,F13>0,1,TRUE,"")) | H13: =IFERROR(INDEX({"","Sangat Rendah","Rendah","Sedang","Tinggi","Sangat Tinggi"},G13+1),"") | O13: =IF(A13="","",IF(AND(M13<>"",N13<>""),M13*N13,IF(AND(D13<>"",E13<>""),D13*E13,""))) | P13: =IF(O13="","",IFS(O13>=20,5,O13>=16,4,O13>=11,3,O13>=6,2,O13>0,1,TRUE,"")) | Q13: =IFERROR(INDEX({"","Sangat Rendah","Rendah","Sedang","Tinggi","Sangat Tinggi"},P13+1),"") | R13: =IFERROR(XLOOKUP(C13,SELERA_RISIKO!$C$5:$C$11,SELERA_RISIKO!$D$5:$D$11),"") | S13: =IF(AND(P13<>"",R13<>""),IF(P13>R13,"YA ⚠","tidak"),"")
B14: =IFERROR(XLOOKUP(A14,IDENTIFIKASI!$B:$B,IDENTIFIKASI!$G:$G),"") | C14: =IFERROR(XLOOKUP(A14,IDENTIFIKASI!$B:$B,IDENTIFIKASI!$H:$H),"") | F14: =IF(AND(D14<>"",E14<>""),D14*E14,"") | G14: =IF(F14="","",IFS(F14>=20,5,F14>=16,4,F14>=11,3,F14>=6,2,F14>0,1,TRUE,"")) | H14: =IFERROR(INDEX({"","Sangat Rendah","Rendah","Sedang","Tinggi","Sangat Tinggi"},G14+1),"") | O14: =IF(A14="","",IF(AND(M14<>"",N14<>""),M14*N14,IF(AND(D14<>"",E14<>""),D14*E14,""))) | P14: =IF(O14="","",IFS(O14>=20,5,O14>=16,4,O14>=11,3,O14>=6,2,O14>0,1,TRUE,"")) | Q14: =IFERROR(INDEX({"","Sangat Rendah","Rendah","Sedang","Tinggi","Sangat Tinggi"},P14+1),"") | R14: =IFERROR(XLOOKUP(C14,SELERA_RISIKO!$C$5:$C$11,SELERA_RISIKO!$D$5:$D$11),"") | S14: =IF(AND(P14<>"",R14<>""),IF(P14>R14,"YA ⚠","tidak"),"")
... B52: =IFERROR(XLOOKUP(A52,IDENTIFIKASI!$B:$B,IDENTIFIKASI!$G:$G),"") | C52: =IFERROR(XLOOKUP(A52,IDENTIFIKASI!$B:$B,IDENTIFIKASI!$H:$H),"") | F52: =IF(AND(D52<>"",E52<>""),D52*E52,"") | G52: =IF(F52="","",IFS(F52>=20,5,F52>=16,4,F52>=11,3,F52>=6,2,F52>0,1,TRUE,"")) | H52: =IFERROR(INDEX({"","Sangat Rendah","Rendah","Sedang","Tinggi","Sangat Tinggi"},G52+1),"") | O52: =IF(A52="","",IF(AND(M52<>"",N52<>""),M52*N52,IF(AND(D52<>"",E52<>""),D52*E52,""))) | P52: =IF(O52="","",IFS(O52>=20,5,O52>=16,4,O52>=11,3,O52>=6,2,O52>0,1,TRUE,"")) | Q52: =IFERROR(INDEX({"","Sangat Rendah","Rendah","Sedang","Tinggi","Sangat Tinggi"},P52+1),"") | R52: =IFERROR(XLOOKUP(C52,SELERA_RISIKO!$C$5:$C$11,SELERA_RISIKO!$D$5:$D$11),"") | S52: =IF(AND(P52<>"",R52<>""),IF(P52>R52,"YA ⚠","tidak"),"")

Sheet EVALUASI
A1: [6] EVALUASI RISIKO — Daftar Prioritas & Heatmap 5×5
A2: A. RISIKO PRIORITAS (Di Atas Selera Risiko)
A3: Kode Risiko | B3: Pernyataan Risiko | C3: Kategori | D3: Proses Bisnis | E3: Skor Inheren | F3: Level Inheren | G3: Skor Residual | H3: Level Residual | I3: Threshold | J3: Status
A4: =IFERROR(FILTER(ANALISIS!A3:T52,ANALISIS!S3:S52="YA ⚠"),"Belum ada risiko prioritas — pastikan sheet [5] ANALISIS sudah diisi dan threshold [2] sudah ditetapkan")
A5: Formula FILTER untuk kolom A4 (salin ke A4, lalu expand): =IFERROR(FILTER(ANALISIS!A3:T52,ANALISIS!S3:S52="YA ⚠"),"Belum ada risiko prioritas")
A8: B. HEATMAP 5×5 — RISIKO RESIDUAL
B9: K\D → | C9: Dampak 1 | D9: Dampak 2 | E9: Dampak 3 | F9: Dampak 4 | G9: Dampak 5
B10: K=5 | C10: =IFERROR(TEXTJOIN(", ",TRUE,IF((ANALISIS!M3:M52=5)*(ANALISIS!N3:N52=1),ANALISIS!A3:A52,""))&IF(COUNTIFS(ANALISIS!M3:M52,5,ANALISIS!N3:N52,1)=0,"—",""),"—") | D10: =IFERROR(TEXTJOIN(", ",TRUE,IF((ANALISIS!M3:M52=5)*(ANALISIS!N3:N52=2),ANALISIS!A3:A52,""))&IF(COUNTIFS(ANALISIS!M3:M52,5,ANALISIS!N3:N52,2)=0,"—",""),"—") | E10: =IFERROR(TEXTJOIN(", ",TRUE,IF((ANALISIS!M3:M52=5)*(ANALISIS!N3:N52=3),ANALISIS!A3:A52,""))&IF(COUNTIFS(ANALISIS!M3:M52,5,ANALISIS!N3:N52,3)=0,"—",""),"—") | F10: =IFERROR(TEXTJOIN(", ",TRUE,IF((ANALISIS!M3:M52=5)*(ANALISIS!N3:N52=4),ANALISIS!A3:A52,""))&IF(COUNTIFS(ANALISIS!M3:M52,5,ANALISIS!N3:N52,4)=0,"—",""),"—") | G10: =IFERROR(TEXTJOIN(", ",TRUE,IF((ANALISIS!M3:M52=5)*(ANALISIS!N3:N52=5),ANALISIS!A3:A52,""))&IF(COUNTIFS(ANALISIS!M3:M52,5,ANALISIS!N3:N52,5)=0,"—",""),"—")
B11: K=4 | C11: =IFERROR(TEXTJOIN(", ",TRUE,IF((ANALISIS!M3:M52=4)*(ANALISIS!N3:N52=1),ANALISIS!A3:A52,""))&IF(COUNTIFS(ANALISIS!M3:M52,4,ANALISIS!N3:N52,1)=0,"—",""),"—") | D11: =IFERROR(TEXTJOIN(", ",TRUE,IF((ANALISIS!M3:M52=4)*(ANALISIS!N3:N52=2),ANALISIS!A3:A52,""))&IF(COUNTIFS(ANALISIS!M3:M52,4,ANALISIS!N3:N52,2)=0,"—",""),"—") | E11: =IFERROR(TEXTJOIN(", ",TRUE,IF((ANALISIS!M3:M52=4)*(ANALISIS!N3:N52=3),ANALISIS!A3:A52,""))&IF(COUNTIFS(ANALISIS!M3:M52,4,ANALISIS!N3:N52,3)=0,"—",""),"—") | F11: =IFERROR(TEXTJOIN(", ",TRUE,IF((ANALISIS!M3:M52=4)*(ANALISIS!N3:N52=4),ANALISIS!A3:A52,""))&IF(COUNTIFS(ANALISIS!M3:M52,4,ANALISIS!N3:N52,4)=0,"—",""),"—") | G11: =IFERROR(TEXTJOIN(", ",TRUE,IF((ANALISIS!M3:M52=4)*(ANALISIS!N3:N52=5),ANALISIS!A3:A52,""))&IF(COUNTIFS(ANALISIS!M3:M52,4,ANALISIS!N3:N52,5)=0,"—",""),"—")
B12: K=3 | C12: =IFERROR(TEXTJOIN(", ",TRUE,IF((ANALISIS!M3:M52=3)*(ANALISIS!N3:N52=1),ANALISIS!A3:A52,""))&IF(COUNTIFS(ANALISIS!M3:M52,3,ANALISIS!N3:N52,1)=0,"—",""),"—") | D12: =IFERROR(TEXTJOIN(", ",TRUE,IF((ANALISIS!M3:M52=3)*(ANALISIS!N3:N52=2),ANALISIS!A3:A52,""))&IF(COUNTIFS(ANALISIS!M3:M52,3,ANALISIS!N3:N52,2)=0,"—",""),"—") | E12: =IFERROR(TEXTJOIN(", ",TRUE,IF((ANALISIS!M3:M52=3)*(ANALISIS!N3:N52=3),ANALISIS!A3:A52,""))&IF(COUNTIFS(ANALISIS!M3:M52,3,ANALISIS!N3:N52,3)=0,"—",""),"—") | F12: =IFERROR(TEXTJOIN(", ",TRUE,IF((ANALISIS!M3:M52=3)*(ANALISIS!N3:N52=4),ANALISIS!A3:A52,""))&IF(COUNTIFS(ANALISIS!M3:M52,3,ANALISIS!N3:N52,4)=0,"—",""),"—") | G12: =IFERROR(TEXTJOIN(", ",TRUE,IF((ANALISIS!M3:M52=3)*(ANALISIS!N3:N52=5),ANALISIS!A3:A52,""))&IF(COUNTIFS(ANALISIS!M3:M52,3,ANALISIS!N3:N52,5)=0,"—",""),"—")
B13: K=2 | C13: =IFERROR(TEXTJOIN(", ",TRUE,IF((ANALISIS!M3:M52=2)*(ANALISIS!N3:N52=1),ANALISIS!A3:A52,""))&IF(COUNTIFS(ANALISIS!M3:M52,2,ANALISIS!N3:N52,1)=0,"—",""),"—") | D13: =IFERROR(TEXTJOIN(", ",TRUE,IF((ANALISIS!M3:M52=2)*(ANALISIS!N3:N52=2),ANALISIS!A3:A52,""))&IF(COUNTIFS(ANALISIS!M3:M52,2,ANALISIS!N3:N52,2)=0,"—",""),"—") | E13: =IFERROR(TEXTJOIN(", ",TRUE,IF((ANALISIS!M3:M52=2)*(ANALISIS!N3:N52=3),ANALISIS!A3:A52,""))&IF(COUNTIFS(ANALISIS!M3:M52,2,ANALISIS!N3:N52,3)=0,"—",""),"—") | F13: =IFERROR(TEXTJOIN(", ",TRUE,IF((ANALISIS!M3:M52=2)*(ANALISIS!N3:N52=4),ANALISIS!A3:A52,""))&IF(COUNTIFS(ANALISIS!M3:M52,2,ANALISIS!N3:N52,4)=0,"—",""),"—") | G13: =IFERROR(TEXTJOIN(", ",TRUE,IF((ANALISIS!M3:M52=2)*(ANALISIS!N3:N52=5),ANALISIS!A3:A52,""))&IF(COUNTIFS(ANALISIS!M3:M52,2,ANALISIS!N3:N52,5)=0,"—",""),"—")
B14: K=1 | C14: =IFERROR(TEXTJOIN(", ",TRUE,IF((ANALISIS!M3:M52=1)*(ANALISIS!N3:N52=1),ANALISIS!A3:A52,""))&IF(COUNTIFS(ANALISIS!M3:M52,1,ANALISIS!N3:N52,1)=0,"—",""),"—") | D14: =IFERROR(TEXTJOIN(", ",TRUE,IF((ANALISIS!M3:M52=1)*(ANALISIS!N3:N52=2),ANALISIS!A3:A52,""))&IF(COUNTIFS(ANALISIS!M3:M52,1,ANALISIS!N3:N52,2)=0,"—",""),"—") | E14: =IFERROR(TEXTJOIN(", ",TRUE,IF((ANALISIS!M3:M52=1)*(ANALISIS!N3:N52=3),ANALISIS!A3:A52,""))&IF(COUNTIFS(ANALISIS!M3:M52,1,ANALISIS!N3:N52,3)=0,"—",""),"—") | F14: =IFERROR(TEXTJOIN(", ",TRUE,IF((ANALISIS!M3:M52=1)*(ANALISIS!N3:N52=4),ANALISIS!A3:A52,""))&IF(COUNTIFS(ANALISIS!M3:M52,1,ANALISIS!N3:N52,4)=0,"—",""),"—") | G14: =IFERROR(TEXTJOIN(", ",TRUE,IF((ANALISIS!M3:M52=1)*(ANALISIS!N3:N52=5),ANALISIS!A3:A52,""))&IF(COUNTIFS(ANALISIS!M3:M52,1,ANALISIS!N3:N52,5)=0,"—",""),"—")
A16: 🔴 Sangat Tinggi (≥20) 🟠 Tinggi (16–19) 🟡 Sedang (11–15) 🟨 Rendah (6–10) 🟢 Sangat Rendah (1–5)

Sheet EVAL_PENG
A1: [7] EVALUASI PENGENDALIAN UTAMA — Risiko Prioritas
A2: Isi kolom B (Kode Risiko) dengan kode dari risiko PRIORITAS (kolom S = "YA ⚠" di sheet [5] ANALISIS). Kolom lain terisi otomatis.
A3: No | B3: Kode Risiko (prioritas) | C3: Pernyataan Risiko | D3: Pengendalian Eksisting (dari [5] ANALISIS) | E3: Pengendalian Utama (isi manual) | F3: Catatan APIP
A4: =IF(B4<>"",ROW()-3,"") | C4: =IFERROR(XLOOKUP(B4,ANALISIS!$A:$A,ANALISIS!$B:$B),"") | D4: =IFERROR(XLOOKUP(B4,ANALISIS!$A:$A,ANALISIS!$J:$J),"")
A5: =IF(B5<>"",ROW()-3,"") | C5: =IFERROR(XLOOKUP(B5,ANALISIS!$A:$A,ANALISIS!$B:$B),"") | D5: =IFERROR(XLOOKUP(B5,ANALISIS!$A:$A,ANALISIS!$J:$J),"")
A6: =IF(B6<>"",ROW()-3,"") | C6: =IFERROR(XLOOKUP(B6,ANALISIS!$A:$A,ANALISIS!$B:$B),"") | D6: =IFERROR(XLOOKUP(B6,ANALISIS!$A:$A,ANALISIS!$J:$J),"")
A7: =IF(B7<>"",ROW()-3,"") | C7: =IFERROR(XLOOKUP(B7,ANALISIS!$A:$A,ANALISIS!$B:$B),"") | D7: =IFERROR(XLOOKUP(B7,ANALISIS!$A:$A,ANALISIS!$J:$J),"")
A8: =IF(B8<>"",ROW()-3,"") | C8: =IFERROR(XLOOKUP(B8,ANALISIS!$A:$A,ANALISIS!$B:$B),"") | D8: =IFERROR(XLOOKUP(B8,ANALISIS!$A:$A,ANALISIS!$J:$J),"")
A9: =IF(B9<>"",ROW()-3,"") | C9: =IFERROR(XLOOKUP(B9,ANALISIS!$A:$A,ANALISIS!$B:$B),"") | D9: =IFERROR(XLOOKUP(B9,ANALISIS!$A:$A,ANALISIS!$J:$J),"")
A10: =IF(B10<>"",ROW()-3,"") | C10: =IFERROR(XLOOKUP(B10,ANALISIS!$A:$A,ANALISIS!$B:$B),"") | D10: =IFERROR(XLOOKUP(B10,ANALISIS!$A:$A,ANALISIS!$J:$J),"")
A11: =IF(B11<>"",ROW()-3,"") | C11: =IFERROR(XLOOKUP(B11,ANALISIS!$A:$A,ANALISIS!$B:$B),"") | D11: =IFERROR(XLOOKUP(B11,ANALISIS!$A:$A,ANALISIS!$J:$J),"")
A12: =IF(B12<>"",ROW()-3,"") | C12: =IFERROR(XLOOKUP(B12,ANALISIS!$A:$A,ANALISIS!$B:$B),"") | D12: =IFERROR(XLOOKUP(B12,ANALISIS!$A:$A,ANALISIS!$J:$J),"")
A13: =IF(B13<>"",ROW()-3,"") | C13: =IFERROR(XLOOKUP(B13,ANALISIS!$A:$A,ANALISIS!$B:$B),"") | D13: =IFERROR(XLOOKUP(B13,ANALISIS!$A:$A,ANALISIS!$J:$J),"")
A14: =IF(B14<>"",ROW()-3,"") | C14: =IFERROR(XLOOKUP(B14,ANALISIS!$A:$A,ANALISIS!$B:$B),"") | D14: =IFERROR(XLOOKUP(B14,ANALISIS!$A:$A,ANALISIS!$J:$J),"")
A15: =IF(B15<>"",ROW()-3,"") | C15: =IFERROR(XLOOKUP(B15,ANALISIS!$A:$A,ANALISIS!$B:$B),"") | D15: =IFERROR(XLOOKUP(B15,ANALISIS!$A:$A,ANALISIS!$J:$J),"")
... A53: =IF(B53<>"",ROW()-3,"") | C53: =IFERROR(XLOOKUP(B53,ANALISIS!$A:$A,ANALISIS!$B:$B),"") | D53: =IFERROR(XLOOKUP(B53,ANALISIS!$A:$A,ANALISIS!$J:$J),"")

Sheet PROGRAM_AUDIT
A1: [8] PROGRAM KERJA AUDIT — Kecukupan Pengendalian ≠ Memadai
A2: Isi kolom A (Kode Risiko) untuk risiko dengan kecukupan pengendalian: Cukup / Kurang / Tidak Memiliki. Kolom Uraian dapat diedit setelah terisi otomatis.
A3: Kode Risiko | B3: Pernyataan Risiko | C3: Kecukupan Pengendalian | D3: Uraian Program Kerja Audit (otomatis, dapat diedit) | E3: No. KKA | F3: Waktu Pelaksanaan | G3: Dilaksanakan Oleh | H3: Catatan
B4: =IFERROR(XLOOKUP(A4,ANALISIS!$A:$A,ANALISIS!$B:$B),"") | C4: =IFERROR(XLOOKUP(A4,ANALISIS!$A:$A,ANALISIS!$L:$L),"") | D4: =IF(A4="","","Pengujian atas kecukupan pengendalian terhadap risiko "&A4&": "&IFERROR(XLOOKUP(A4,ANALISIS!$A:$A,ANALISIS!$B:$B),"")&". Pengendalian eksisting: "&IFERROR(XLOOKUP(A4,ANALISIS!$A:$A,ANALISIS!$J:$J),"(tidak ada)")&". Pengendalian utama: "&IFERROR(XLOOKUP(A4,EVAL_PENG!$B:$B,EVAL_PENG!$E:$E),"(belum ditetapkan)")&". Penyebab terkait: "&IFERROR(TEXTJOIN(", ",TRUE,IF(PENYEBAB!$B$4:$B$153=A4,PENYEBAB!$E$4:$E$153,"")),"(belum diisi)")&".")
B5: =IFERROR(XLOOKUP(A5,ANALISIS!$A:$A,ANALISIS!$B:$B),"") | C5: =IFERROR(XLOOKUP(A5,ANALISIS!$A:$A,ANALISIS!$L:$L),"") | D5: =IF(A5="","","Pengujian atas kecukupan pengendalian terhadap risiko "&A5&": "&IFERROR(XLOOKUP(A5,ANALISIS!$A:$A,ANALISIS!$B:$B),"")&". Pengendalian eksisting: "&IFERROR(XLOOKUP(A5,ANALISIS!$A:$A,ANALISIS!$J:$J),"(tidak ada)")&". Pengendalian utama: "&IFERROR(XLOOKUP(A5,EVAL_PENG!$B:$B,EVAL_PENG!$E:$E),"(belum ditetapkan)")&". Penyebab terkait: "&IFERROR(TEXTJOIN(", ",TRUE,IF(PENYEBAB!$B$4:$B$153=A5,PENYEBAB!$E$4:$E$153,"")),"(belum diisi)")&".")
B6: =IFERROR(XLOOKUP(A6,ANALISIS!$A:$A,ANALISIS!$B:$B),"") | C6: =IFERROR(XLOOKUP(A6,ANALISIS!$A:$A,ANALISIS!$L:$L),"") | D6: =IF(A6="","","Pengujian atas kecukupan pengendalian terhadap risiko "&A6&": "&IFERROR(XLOOKUP(A6,ANALISIS!$A:$A,ANALISIS!$B:$B),"")&". Pengendalian eksisting: "&IFERROR(XLOOKUP(A6,ANALISIS!$A:$A,ANALISIS!$J:$J),"(tidak ada)")&". Pengendalian utama: "&IFERROR(XLOOKUP(A6,EVAL_PENG!$B:$B,EVAL_PENG!$E:$E),"(belum ditetapkan)")&". Penyebab terkait: "&IFERROR(TEXTJOIN(", ",TRUE,IF(PENYEBAB!$B$4:$B$153=A6,PENYEBAB!$E$4:$E$153,"")),"(belum diisi)")&".")
B7: =IFERROR(XLOOKUP(A7,ANALISIS!$A:$A,ANALISIS!$B:$B),"") | C7: =IFERROR(XLOOKUP(A7,ANALISIS!$A:$A,ANALISIS!$L:$L),"") | D7: =IF(A7="","","Pengujian atas kecukupan pengendalian terhadap risiko "&A7&": "&IFERROR(XLOOKUP(A7,ANALISIS!$A:$A,ANALISIS!$B:$B),"")&". Pengendalian eksisting: "&IFERROR(XLOOKUP(A7,ANALISIS!$A:$A,ANALISIS!$J:$J),"(tidak ada)")&". Pengendalian utama: "&IFERROR(XLOOKUP(A7,EVAL_PENG!$B:$B,EVAL_PENG!$E:$E),"(belum ditetapkan)")&". Penyebab terkait: "&IFERROR(TEXTJOIN(", ",TRUE,IF(PENYEBAB!$B$4:$B$153=A7,PENYEBAB!$E$4:$E$153,"")),"(belum diisi)")&".")
B8: =IFERROR(XLOOKUP(A8,ANALISIS!$A:$A,ANALISIS!$B:$B),"") | C8: =IFERROR(XLOOKUP(A8,ANALISIS!$A:$A,ANALISIS!$L:$L),"") | D8: =IF(A8="","","Pengujian atas kecukupan pengendalian terhadap risiko "&A8&": "&IFERROR(XLOOKUP(A8,ANALISIS!$A:$A,ANALISIS!$B:$B),"")&". Pengendalian eksisting: "&IFERROR(XLOOKUP(A8,ANALISIS!$A:$A,ANALISIS!$J:$J),"(tidak ada)")&". Pengendalian utama: "&IFERROR(XLOOKUP(A8,EVAL_PENG!$B:$B,EVAL_PENG!$E:$E),"(belum ditetapkan)")&". Penyebab terkait: "&IFERROR(TEXTJOIN(", ",TRUE,IF(PENYEBAB!$B$4:$B$153=A8,PENYEBAB!$E$4:$E$153,"")),"(belum diisi)")&".")
B9: =IFERROR(XLOOKUP(A9,ANALISIS!$A:$A,ANALISIS!$B:$B),"") | C9: =IFERROR(XLOOKUP(A9,ANALISIS!$A:$A,ANALISIS!$L:$L),"") | D9: =IF(A9="","","Pengujian atas kecukupan pengendalian terhadap risiko "&A9&": "&IFERROR(XLOOKUP(A9,ANALISIS!$A:$A,ANALISIS!$B:$B),"")&". Pengendalian eksisting: "&IFERROR(XLOOKUP(A9,ANALISIS!$A:$A,ANALISIS!$J:$J),"(tidak ada)")&". Pengendalian utama: "&IFERROR(XLOOKUP(A9,EVAL_PENG!$B:$B,EVAL_PENG!$E:$E),"(belum ditetapkan)")&". Penyebab terkait: "&IFERROR(TEXTJOIN(", ",TRUE,IF(PENYEBAB!$B$4:$B$153=A9,PENYEBAB!$E$4:$E$153,"")),"(belum diisi)")&".")
B10: =IFERROR(XLOOKUP(A10,ANALISIS!$A:$A,ANALISIS!$B:$B),"") | C10: =IFERROR(XLOOKUP(A10,ANALISIS!$A:$A,ANALISIS!$L:$L),"") | D10: =IF(A10="","","Pengujian atas kecukupan pengendalian terhadap risiko "&A10&": "&IFERROR(XLOOKUP(A10,ANALISIS!$A:$A,ANALISIS!$B:$B),"")&". Pengendalian eksisting: "&IFERROR(XLOOKUP(A10,ANALISIS!$A:$A,ANALISIS!$J:$J),"(tidak ada)")&". Pengendalian utama: "&IFERROR(XLOOKUP(A10,EVAL_PENG!$B:$B,EVAL_PENG!$E:$E),"(belum ditetapkan)")&". Penyebab terkait: "&IFERROR(TEXTJOIN(", ",TRUE,IF(PENYEBAB!$B$4:$B$153=A10,PENYEBAB!$E$4:$E$153,"")),"(belum diisi)")&".")
B11: =IFERROR(XLOOKUP(A11,ANALISIS!$A:$A,ANALISIS!$B:$B),"") | C11: =IFERROR(XLOOKUP(A11,ANALISIS!$A:$A,ANALISIS!$L:$L),"") | D11: =IF(A11="","","Pengujian atas kecukupan pengendalian terhadap risiko "&A11&": "&IFERROR(XLOOKUP(A11,ANALISIS!$A:$A,ANALISIS!$B:$B),"")&". Pengendalian eksisting: "&IFERROR(XLOOKUP(A11,ANALISIS!$A:$A,ANALISIS!$J:$J),"(tidak ada)")&". Pengendalian utama: "&IFERROR(XLOOKUP(A11,EVAL_PENG!$B:$B,EVAL_PENG!$E:$E),"(belum ditetapkan)")&". Penyebab terkait: "&IFERROR(TEXTJOIN(", ",TRUE,IF(PENYEBAB!$B$4:$B$153=A11,PENYEBAB!$E$4:$E$153,"")),"(belum diisi)")&".")
B12: =IFERROR(XLOOKUP(A12,ANALISIS!$A:$A,ANALISIS!$B:$B),"") | C12: =IFERROR(XLOOKUP(A12,ANALISIS!$A:$A,ANALISIS!$L:$L),"") | D12: =IF(A12="","","Pengujian atas kecukupan pengendalian terhadap risiko "&A12&": "&IFERROR(XLOOKUP(A12,ANALISIS!$A:$A,ANALISIS!$B:$B),"")&". Pengendalian eksisting: "&IFERROR(XLOOKUP(A12,ANALISIS!$A:$A,ANALISIS!$J:$J),"(tidak ada)")&". Pengendalian utama: "&IFERROR(XLOOKUP(A12,EVAL_PENG!$B:$B,EVAL_PENG!$E:$E),"(belum ditetapkan)")&". Penyebab terkait: "&IFERROR(TEXTJOIN(", ",TRUE,IF(PENYEBAB!$B$4:$B$153=A12,PENYEBAB!$E$4:$E$153,"")),"(belum diisi)")&".")
B13: =IFERROR(XLOOKUP(A13,ANALISIS!$A:$A,ANALISIS!$B:$B),"") | C13: =IFERROR(XLOOKUP(A13,ANALISIS!$A:$A,ANALISIS!$L:$L),"") | D13: =IF(A13="","","Pengujian atas kecukupan pengendalian terhadap risiko "&A13&": "&IFERROR(XLOOKUP(A13,ANALISIS!$A:$A,ANALISIS!$B:$B),"")&". Pengendalian eksisting: "&IFERROR(XLOOKUP(A13,ANALISIS!$A:$A,ANALISIS!$J:$J),"(tidak ada)")&". Pengendalian utama: "&IFERROR(XLOOKUP(A13,EVAL_PENG!$B:$B,EVAL_PENG!$E:$E),"(belum ditetapkan)")&". Penyebab terkait: "&IFERROR(TEXTJOIN(", ",TRUE,IF(PENYEBAB!$B$4:$B$153=A13,PENYEBAB!$E$4:$E$153,"")),"(belum diisi)")&".")
B14: =IFERROR(XLOOKUP(A14,ANALISIS!$A:$A,ANALISIS!$B:$B),"") | C14: =IFERROR(XLOOKUP(A14,ANALISIS!$A:$A,ANALISIS!$L:$L),"") | D14: =IF(A14="","","Pengujian atas kecukupan pengendalian terhadap risiko "&A14&": "&IFERROR(XLOOKUP(A14,ANALISIS!$A:$A,ANALISIS!$B:$B),"")&". Pengendalian eksisting: "&IFERROR(XLOOKUP(A14,ANALISIS!$A:$A,ANALISIS!$J:$J),"(tidak ada)")&". Pengendalian utama: "&IFERROR(XLOOKUP(A14,EVAL_PENG!$B:$B,EVAL_PENG!$E:$E),"(belum ditetapkan)")&". Penyebab terkait: "&IFERROR(TEXTJOIN(", ",TRUE,IF(PENYEBAB!$B$4:$B$153=A14,PENYEBAB!$E$4:$E$153,"")),"(belum diisi)")&".")
B15: =IFERROR(XLOOKUP(A15,ANALISIS!$A:$A,ANALISIS!$B:$B),"") | C15: =IFERROR(XLOOKUP(A15,ANALISIS!$A:$A,ANALISIS!$L:$L),"") | D15: =IF(A15="","","Pengujian atas kecukupan pengendalian terhadap risiko "&A15&": "&IFERROR(XLOOKUP(A15,ANALISIS!$A:$A,ANALISIS!$B:$B),"")&". Pengendalian eksisting: "&IFERROR(XLOOKUP(A15,ANALISIS!$A:$A,ANALISIS!$J:$J),"(tidak ada)")&". Pengendalian utama: "&IFERROR(XLOOKUP(A15,EVAL_PENG!$B:$B,EVAL_PENG!$E:$E),"(belum ditetapkan)")&". Penyebab terkait: "&IFERROR(TEXTJOIN(", ",TRUE,IF(PENYEBAB!$B$4:$B$153=A15,PENYEBAB!$E$4:$E$153,"")),"(belum diisi)")&".")
... B53: =IFERROR(XLOOKUP(A53,ANALISIS!$A:$A,ANALISIS!$B:$B),"") | C53: =IFERROR(XLOOKUP(A53,ANALISIS!$A:$A,ANALISIS!$L:$L),"") | D53: =IF(A53="","","Pengujian atas kecukupan pengendalian terhadap risiko "&A53&": "&IFERROR(XLOOKUP(A53,ANALISIS!$A:$A,ANALISIS!$B:$B),"")&". Pengendalian eksisting: "&IFERROR(XLOOKUP(A53,ANALISIS!$A:$A,ANALISIS!$J:$J),"(tidak ada)")&". Pengendalian utama: "&IFERROR(XLOOKUP(A53,EVAL_PENG!$B:$B,EVAL_PENG!$E:$E),"(belum ditetapkan)")&". Penyebab terkait: "&IFERROR(TEXTJOIN(", ",TRUE,IF(PENYEBAB!$B$4:$B$153=A53,PENYEBAB!$E$4:$E$153,"")),"(belum diisi)")&".")

Sheet RTP
A1: [9] RENCANA TINDAK PENGENDALIAN — Format Lampiran 10
A2: Isi kolom A (Kode Penyebab) dari penyebab risiko PRIORITAS. Salin dari kolom E sheet [4] PENYEBAB, hanya untuk penyebab dari risiko yang di_atas_selera = YA.
A3: Kode Penyebab (dari [4]) | B3: Kode Risiko | C3: Pernyataan Risiko | D3: Akar Penyebab | E3: Kegiatan Pengendalian Eksisting | F3: Klasifikasi SPIP | G3: Penanggung Jawab | H3: Indikator Keluaran | I3: Target Waktu | J3: Kemungkinan Rencana (1–5) | K3: Dampak Rencana (1–5) | L3: Besaran RTP | M3: Level RTP | N3: Label RTP | O3: Catatan
B4: =IFERROR(XLOOKUP(A4,PENYEBAB!$E:$E,PENYEBAB!$B:$B),"") | C4: =IFERROR(XLOOKUP(A4,PENYEBAB!$E:$E,PENYEBAB!$C:$C),"") | D4: =IFERROR(XLOOKUP(A4,PENYEBAB!$E:$E,PENYEBAB!$K:$K),"") | E4: =IFERROR(XLOOKUP(A4,PENYEBAB!$E:$E,PENYEBAB!$L:$L),"") | L4: =IF(AND(J4<>"",K4<>""),J4*K4,"") | M4: =IF(L4="","",IFS(L4>=20,5,L4>=16,4,L4>=11,3,L4>=6,2,L4>0,1,TRUE,"")) | N4: =IFERROR(INDEX({"","Sangat Rendah","Rendah","Sedang","Tinggi","Sangat Tinggi"},M4+1),"")
B5: =IFERROR(XLOOKUP(A5,PENYEBAB!$E:$E,PENYEBAB!$B:$B),"") | C5: =IFERROR(XLOOKUP(A5,PENYEBAB!$E:$E,PENYEBAB!$C:$C),"") | D5: =IFERROR(XLOOKUP(A5,PENYEBAB!$E:$E,PENYEBAB!$K:$K),"") | E5: =IFERROR(XLOOKUP(A5,PENYEBAB!$E:$E,PENYEBAB!$L:$L),"") | L5: =IF(AND(J5<>"",K5<>""),J5*K5,"") | M5: =IF(L5="","",IFS(L5>=20,5,L5>=16,4,L5>=11,3,L5>=6,2,L5>0,1,TRUE,"")) | N5: =IFERROR(INDEX({"","Sangat Rendah","Rendah","Sedang","Tinggi","Sangat Tinggi"},M5+1),"")
B6: =IFERROR(XLOOKUP(A6,PENYEBAB!$E:$E,PENYEBAB!$B:$B),"") | C6: =IFERROR(XLOOKUP(A6,PENYEBAB!$E:$E,PENYEBAB!$C:$C),"") | D6: =IFERROR(XLOOKUP(A6,PENYEBAB!$E:$E,PENYEBAB!$K:$K),"") | E6: =IFERROR(XLOOKUP(A6,PENYEBAB!$E:$E,PENYEBAB!$L:$L),"") | L6: =IF(AND(J6<>"",K6<>""),J6*K6,"") | M6: =IF(L6="","",IFS(L6>=20,5,L6>=16,4,L6>=11,3,L6>=6,2,L6>0,1,TRUE,"")) | N6: =IFERROR(INDEX({"","Sangat Rendah","Rendah","Sedang","Tinggi","Sangat Tinggi"},M6+1),"")
B7: =IFERROR(XLOOKUP(A7,PENYEBAB!$E:$E,PENYEBAB!$B:$B),"") | C7: =IFERROR(XLOOKUP(A7,PENYEBAB!$E:$E,PENYEBAB!$C:$C),"") | D7: =IFERROR(XLOOKUP(A7,PENYEBAB!$E:$E,PENYEBAB!$K:$K),"") | E7: =IFERROR(XLOOKUP(A7,PENYEBAB!$E:$E,PENYEBAB!$L:$L),"") | L7: =IF(AND(J7<>"",K7<>""),J7*K7,"") | M7: =IF(L7="","",IFS(L7>=20,5,L7>=16,4,L7>=11,3,L7>=6,2,L7>0,1,TRUE,"")) | N7: =IFERROR(INDEX({"","Sangat Rendah","Rendah","Sedang","Tinggi","Sangat Tinggi"},M7+1),"")
B8: =IFERROR(XLOOKUP(A8,PENYEBAB!$E:$E,PENYEBAB!$B:$B),"") | C8: =IFERROR(XLOOKUP(A8,PENYEBAB!$E:$E,PENYEBAB!$C:$C),"") | D8: =IFERROR(XLOOKUP(A8,PENYEBAB!$E:$E,PENYEBAB!$K:$K),"") | E8: =IFERROR(XLOOKUP(A8,PENYEBAB!$E:$E,PENYEBAB!$L:$L),"") | L8: =IF(AND(J8<>"",K8<>""),J8*K8,"") | M8: =IF(L8="","",IFS(L8>=20,5,L8>=16,4,L8>=11,3,L8>=6,2,L8>0,1,TRUE,"")) | N8: =IFERROR(INDEX({"","Sangat Rendah","Rendah","Sedang","Tinggi","Sangat Tinggi"},M8+1),"")
B9: =IFERROR(XLOOKUP(A9,PENYEBAB!$E:$E,PENYEBAB!$B:$B),"") | C9: =IFERROR(XLOOKUP(A9,PENYEBAB!$E:$E,PENYEBAB!$C:$C),"") | D9: =IFERROR(XLOOKUP(A9,PENYEBAB!$E:$E,PENYEBAB!$K:$K),"") | E9: =IFERROR(XLOOKUP(A9,PENYEBAB!$E:$E,PENYEBAB!$L:$L),"") | L9: =IF(AND(J9<>"",K9<>""),J9*K9,"") | M9: =IF(L9="","",IFS(L9>=20,5,L9>=16,4,L9>=11,3,L9>=6,2,L9>0,1,TRUE,"")) | N9: =IFERROR(INDEX({"","Sangat Rendah","Rendah","Sedang","Tinggi","Sangat Tinggi"},M9+1),"")
B10: =IFERROR(XLOOKUP(A10,PENYEBAB!$E:$E,PENYEBAB!$B:$B),"") | C10: =IFERROR(XLOOKUP(A10,PENYEBAB!$E:$E,PENYEBAB!$C:$C),"") | D10: =IFERROR(XLOOKUP(A10,PENYEBAB!$E:$E,PENYEBAB!$K:$K),"") | E10: =IFERROR(XLOOKUP(A10,PENYEBAB!$E:$E,PENYEBAB!$L:$L),"") | L10: =IF(AND(J10<>"",K10<>""),J10*K10,"") | M10: =IF(L10="","",IFS(L10>=20,5,L10>=16,4,L10>=11,3,L10>=6,2,L10>0,1,TRUE,"")) | N10: =IFERROR(INDEX({"","Sangat Rendah","Rendah","Sedang","Tinggi","Sangat Tinggi"},M10+1),"")
B11: =IFERROR(XLOOKUP(A11,PENYEBAB!$E:$E,PENYEBAB!$B:$B),"") | C11: =IFERROR(XLOOKUP(A11,PENYEBAB!$E:$E,PENYEBAB!$C:$C),"") | D11: =IFERROR(XLOOKUP(A11,PENYEBAB!$E:$E,PENYEBAB!$K:$K),"") | E11: =IFERROR(XLOOKUP(A11,PENYEBAB!$E:$E,PENYEBAB!$L:$L),"") | L11: =IF(AND(J11<>"",K11<>""),J11*K11,"") | M11: =IF(L11="","",IFS(L11>=20,5,L11>=16,4,L11>=11,3,L11>=6,2,L11>0,1,TRUE,"")) | N11: =IFERROR(INDEX({"","Sangat Rendah","Rendah","Sedang","Tinggi","Sangat Tinggi"},M11+1),"")
B12: =IFERROR(XLOOKUP(A12,PENYEBAB!$E:$E,PENYEBAB!$B:$B),"") | C12: =IFERROR(XLOOKUP(A12,PENYEBAB!$E:$E,PENYEBAB!$C:$C),"") | D12: =IFERROR(XLOOKUP(A12,PENYEBAB!$E:$E,PENYEBAB!$K:$K),"") | E12: =IFERROR(XLOOKUP(A12,PENYEBAB!$E:$E,PENYEBAB!$L:$L),"") | L12: =IF(AND(J12<>"",K12<>""),J12*K12,"") | M12: =IF(L12="","",IFS(L12>=20,5,L12>=16,4,L12>=11,3,L12>=6,2,L12>0,1,TRUE,"")) | N12: =IFERROR(INDEX({"","Sangat Rendah","Rendah","Sedang","Tinggi","Sangat Tinggi"},M12+1),"")
B13: =IFERROR(XLOOKUP(A13,PENYEBAB!$E:$E,PENYEBAB!$B:$B),"") | C13: =IFERROR(XLOOKUP(A13,PENYEBAB!$E:$E,PENYEBAB!$C:$C),"") | D13: =IFERROR(XLOOKUP(A13,PENYEBAB!$E:$E,PENYEBAB!$K:$K),"") | E13: =IFERROR(XLOOKUP(A13,PENYEBAB!$E:$E,PENYEBAB!$L:$L),"") | L13: =IF(AND(J13<>"",K13<>""),J13*K13,"") | M13: =IF(L13="","",IFS(L13>=20,5,L13>=16,4,L13>=11,3,L13>=6,2,L13>0,1,TRUE,"")) | N13: =IFERROR(INDEX({"","Sangat Rendah","Rendah","Sedang","Tinggi","Sangat Tinggi"},M13+1),"")
