Workbook
Name description_level_risiko: data!$Q$11:$Q$1010
Name id_level_risiko: data!$R$11:$R$1010
Name id_level_risiko: #REF!
Name lower_limit_level_risiko: data!$O$11:$O$1010
Name upper_limit_level_risiko: data!$P$11:$P$1010

Sheet Panduan Penggunaan
A2: PANDUAN PENGGUNAAN PUSTAKA RISIKO (RISK LIBRARY)
A3: Untuk Mahkamah Agung RI dan Badan Peradilan di bawahnya
A5: Struktur Template:
A6: 1. Panduan Penggunaan | B6: Sheet ini - berisi instruksi penggunaan pustaka risiko
A7: 2. Master Pustaka Risiko | B7: Sheet utama untuk mendokumentasikan pustaka risiko
A8: 3. Kriteria Penilaian | B8: Definisi skala Likelihood dan Impact yang disesuaikan dengan konteks instansi
A9: 4. Matriks Risiko 5x5 | B9: Visualisasi matriks untuk menentukan level risiko
A10: 5. Kategori Risiko | B10: Master list kategori risiko
A11: 6. Katalog Kontrol | B11: Katalog kontrol standar yang dapat direferensikan
A12: 7. Contoh Pengisian | B12: Contoh konkret pengisian untuk referensi (came with the template)
A14: Cara Menggunakan:
A15: Langkah 1 | B15: Sesuaikan Kriteria Penilaian di sheet 'Kriteria Penilaian' dengan konteks instansi Anda
A16: Langkah 2 | B16: Sesuaikan Kategori Risiko di sheet 'Kategori Risiko' sesuai mandat instansi
A17: Langkah 3 | B17: Mulai mengisi Master Pustaka Risiko dengan risiko-risiko yang teridentifikasi
A18: Langkah 4 | B18: Gunakan dropdown yang tersedia untuk memastikan konsistensi data
A19: Langkah 5 | B19: Review dan validasi dengan stakeholder terkait
A21: Catatan Penting:
A22: - Pustaka Risiko adalah TEMPLATE, bukan daftar risiko aktif (Risk Register)
A23: - Setiap risiko harus memiliki ID unik untuk kemudahan referensi
A24: - Pernyataan risiko harus menggunakan format: [Penyebab] → [Peristiwa] → [Dampak]
A25: - Lakukan review dan update Pustaka Risiko minimal setahun sekali

Sheet Proses Bisnis
A1: PROSES BISNIS | F1: DEFINISI - SUBPROSES - KEGIATAN
B2: Probis | C2: Subprobis | D2: Kegiatan
A3: 1 | B3: Manajemen Peradilan | F3: …
A4: 2 | B4: Pelayanan Publik | F4: …
A5: 3 | B5: Administrasi Umum | F5: …
C6: Pengadaan B/J P | G6: …
C7: SDM | G7: …
C8: Keuangan DIPA/Titipan pihak ketiga | G8: …
C9: … | G9: …
A10: 4 | B10: Administrasi Perkara | F10: …
A11: 5 | B11: Administrasi Persidangan | F11: …
A12: 6 | B12: Pengawasan (Internal dan Eksternal) | F12: …
A13: 7 | B13: Penanganan Pengaduan | F13: …

Sheet Master Pustaka Risiko
A1: MASTER PUSTAKA RISIKO (RISK LIBRARY)
A2: ID Risiko | B2: Level | C2: Proses Bisnis | D2: Kegiatan | E2: Kategori Risiko | F2: Nama Risiko | G2: Deskripsi Risiko | H2: Pernyataan Risiko (Penyebab Utama → Peristiwa → Dampak) | I2: Penyebab Utama | J2: Daftar Penyebab | K2: Dampak Potensial | L2: Sasaran Strategis Terkait | M2: Likelihood (Inherent) | N2: Impact (Inherent) | O2: Skor Risiko (Inherent) | P2: Level Risiko (Inherent) | Q2: Kontrol yang Direkomendasikan | R2: Efektivitas Kontrol Target | S2: Likelihood (Residual Target) | T2: Impact (Residual Target) | U2: Skor Risiko (Residual Target) | V2: Level Risiko (Residual Target) | W2: Strategi Treatment | X2: Rencana Aksi Mitigasi | Y2: PIC/Risk Owner | Z2: Catatan
A3: R-001 | B3: Pengadilan Tingkat Pertama | C3: Administrasi Persidangan | E3: Risiko Kecurangan | F3: Gratifikasi dalam rangka mendapatkan prioritas urutan antrean | G3: Risiko ini merujuk pada praktik gratifikasi yang dilakukan oleh pengunjung atau pihak beperkara kepada petugas antrean, dengan harapan nomor antreannya dapat didahulukan, diprioritaskan, atau dipercepat proses pendaftarannya dengan mengabaikan prosedur antrean yang semestinya | H3: ="["&I3&"] menyebabkan ["&F3&"]; sehingga berakibat pada ["&K3&"]" -> [Keterbatasan Sistem Layanan (Penumpukan antrean) yang Bertemu dengan Lemahnya Integritas Petugas di Lini Depan] menyebabkan [Gratifikasi dalam rangka mendapatkan prioritas urutan antrean]; sehingga berakibat pada [Rusaknya citra satuan kerja, menurunkan kepercayaan masyarakat terhadap pengadilan, dan secara luas berdampak buruk pada reputasi lembaga Mahkamah Agung.] | I3: Keterbatasan Sistem Layanan (Penumpukan antrean) yang Bertemu dengan Lemahnya Integritas Petugas di Lini Depan | J3: 1. Faktor Sistem dan Infrastruktur Layanan 1.1. Penumpukan antrean akibat Sistem Manual: Banyak pengadilan mengidentifikasi bahwa antrean panjang terjadi karena sistem pendaftaran dan pengambilan antrean masih dilakukan secara manual atau kurangnya optimalisasi antrean online. Hal ini menyebabkan leher botol (bottleneck) di ruang tunggu. 1.2. Kurangnya Pemahaman Pengunjung Terhadap Sistem Elektronik: Sebagian pengunjung kurang memahami cara menggunakan fasilitas pendaftaran atau antrean online (seperti aplikasi antrean mandiri), sehingga mereka masih bergantung pada antrean kedatangan fisik yang rentan dimanipulasi petugas. 2. Faktor Eksternal (Motivasi Pengunjung/Pihak beperkara) Keinginan Mendapat Layanan Instan/Cepat: Adanya kepentingan dari pihak beperkara atau pengunjung yang tidak sabar menghadapi antrean panjang dan memiliki keinginan/dorongan untuk diproses, dilayani, atau didahulukan secara lebih cepat dibandingkan pengunjung lain. 3. Faktor Integritas dan Pemahaman Petugas (Internal) 3.1. Lemahnya Integritas Petugas: Kurangnya kepatuhan terhadap kode etik oleh petugas antrean, sekuriti, atau petugas buku tamu, sehingga mudah tergiur oleh iming-iming imbalan. 3.2. Budaya Permisif: Adanya anggapan atau pembenaran dari petugas bahwa praktik suap-menyuap, menerima "uang tip", atau menerima gratifikasi sebagai ucapan terima kasih merupakan hal yang wajar dilakukan dalam pelayanan. 3.3. Ketidakpatuhan Terhadap Aturan/SOP: Petugas tidak menerapkan Standar Operasional Prosedur (SOP) atau Surat Keputusan Pimpinan terkait tata tertib penerimaan tamu dan kewajiban pengisian identitas yang jelas. 4. Faktor Pengawasan (Supervisory) Lemahnya Pengawasan Atasan: Kurangnya kontrol, pemantauan (monitoring), dan pengawasan melekat dari pimpinan atau penanggung jawab langsung (seperti Kasubbag Umum, atasan PTSP, atau pejabat terkait) terhadap kinerja petugas keamanan dan petugas antrean di lapangan. | K3: Rusaknya citra satuan kerja, menurunkan kepercayaan masyarakat terhadap pengadilan, dan secara luas berdampak buruk pada reputasi lembaga Mahkamah Agung. | L3: FORMULA LINKED TO B3 | O3: =M3*N3 -> 0 | P3: =IF(O3>=20,"Sangat Tinggi",IF(O3>=16,"Tinggi",IF(O3>=11,"Moderat",IF(O3>=6,"Rendah","Sangat Rendah")))) -> Sangat Rendah | Q3: C-001 | U3: =S3*T3 -> 0 | V3: =IF(U3>=20,"Sangat Tinggi",IF(U3>=16,"Tinggi",IF(U3>=11,"Moderat",IF(U3>=6,"Rendah","Sangat Rendah")))) -> Sangat Rendah
A4: R-002 | O4: =M4*N4 -> 0 | P4: =IF(O4>=20,"Sangat Tinggi",IF(O4>=16,"Tinggi",IF(O4>=11,"Moderat",IF(O4>=6,"Rendah","Sangat Rendah")))) -> Sangat Rendah | U4: =S4*T4 -> 0 | V4: =IF(U4>=20,"Sangat Tinggi",IF(U4>=16,"Tinggi",IF(U4>=11,"Moderat",IF(U4>=6,"Rendah","Sangat Rendah")))) -> Sangat Rendah
A5: R-003 | O5: =M5*N5 -> 0 | P5: =IF(O5>=20,"Sangat Tinggi",IF(O5>=16,"Tinggi",IF(O5>=11,"Moderat",IF(O5>=6,"Rendah","Sangat Rendah")))) -> Sangat Rendah | U5: =S5*T5 -> 0 | V5: =IF(U5>=20,"Sangat Tinggi",IF(U5>=16,"Tinggi",IF(U5>=11,"Moderat",IF(U5>=6,"Rendah","Sangat Rendah")))) -> Sangat Rendah
A6: R-004 | O6: =M6*N6 -> 0 | P6: =IF(O6>=20,"Sangat Tinggi",IF(O6>=16,"Tinggi",IF(O6>=11,"Moderat",IF(O6>=6,"Rendah","Sangat Rendah")))) -> Sangat Rendah | U6: =S6*T6 -> 0 | V6: =IF(U6>=20,"Sangat Tinggi",IF(U6>=16,"Tinggi",IF(U6>=11,"Moderat",IF(U6>=6,"Rendah","Sangat Rendah")))) -> Sangat Rendah
A7: R-005 | O7: =M7*N7 -> 0 | P7: =IF(O7>=20,"Sangat Tinggi",IF(O7>=16,"Tinggi",IF(O7>=11,"Moderat",IF(O7>=6,"Rendah","Sangat Rendah")))) -> Sangat Rendah | U7: =S7*T7 -> 0 | V7: =IF(U7>=20,"Sangat Tinggi",IF(U7>=16,"Tinggi",IF(U7>=11,"Moderat",IF(U7>=6,"Rendah","Sangat Rendah")))) -> Sangat Rendah
A8: R-006 | O8: =M8*N8 -> 0 | P8: =IF(O8>=20,"Sangat Tinggi",IF(O8>=16,"Tinggi",IF(O8>=11,"Moderat",IF(O8>=6,"Rendah","Sangat Rendah")))) -> Sangat Rendah | U8: =S8*T8 -> 0 | V8: =IF(U8>=20,"Sangat Tinggi",IF(U8>=16,"Tinggi",IF(U8>=11,"Moderat",IF(U8>=6,"Rendah","Sangat Rendah")))) -> Sangat Rendah
A9: R-007 | O9: =M9*N9 -> 0 | P9: =IF(O9>=20,"Sangat Tinggi",IF(O9>=16,"Tinggi",IF(O9>=11,"Moderat",IF(O9>=6,"Rendah","Sangat Rendah")))) -> Sangat Rendah | U9: =S9*T9 -> 0 | V9: =IF(U9>=20,"Sangat Tinggi",IF(U9>=16,"Tinggi",IF(U9>=11,"Moderat",IF(U9>=6,"Rendah","Sangat Rendah")))) -> Sangat Rendah
A10: R-008 | O10: =M10*N10 -> 0 | P10: =IF(O10>=20,"Sangat Tinggi",IF(O10>=16,"Tinggi",IF(O10>=11,"Moderat",IF(O10>=6,"Rendah","Sangat Rendah")))) -> Sangat Rendah | U10: =S10*T10 -> 0 | V10: =IF(U10>=20,"Sangat Tinggi",IF(U10>=16,"Tinggi",IF(U10>=11,"Moderat",IF(U10>=6,"Rendah","Sangat Rendah")))) -> Sangat Rendah
A11: R-009 | O11: =M11*N11 -> 0 | P11: =IF(O11>=20,"Sangat Tinggi",IF(O11>=16,"Tinggi",IF(O11>=11,"Moderat",IF(O11>=6,"Rendah","Sangat Rendah")))) -> Sangat Rendah | U11: =S11*T11 -> 0 | V11: =IF(U11>=20,"Sangat Tinggi",IF(U11>=16,"Tinggi",IF(U11>=11,"Moderat",IF(U11>=6,"Rendah","Sangat Rendah")))) -> Sangat Rendah
A12: R-010 | O12: =M12*N12 -> 0 | P12: =IF(O12>=20,"Sangat Tinggi",IF(O12>=16,"Tinggi",IF(O12>=11,"Moderat",IF(O12>=6,"Rendah","Sangat Rendah")))) -> Sangat Rendah | U12: =S12*T12 -> 0 | V12: =IF(U12>=20,"Sangat Tinggi",IF(U12>=16,"Tinggi",IF(U12>=11,"Moderat",IF(U12>=6,"Rendah","Sangat Rendah")))) -> Sangat Rendah

Sheet Sheet1
B3: Risk Management
B4: Memenej risiko terhadap pencapaian sasaran
B5: ?
B6: risiko = sesuatu yang tidak pasti di masa mendatang yang "mengancam" pencapaian tujuan
B7: ingin kita mencapai tujuan = MENURUNKAN risiko
B8: menurunkan?
B9: melakukan PENGENDALIAN/KONTROL
B11: Jika pengendalian/kontrol/IC kita efektif/memadai, maka level/tingkat risiko itu bisa dipastikan TURUN
B12: Jika risiko TURUN maka Sasaran lebih diyakini dapat tercapai.
B14: Apakah kita kemudian menurunkan risiko: 1) semaksimal mungkin, 2) sampai risikonya habis/tak bersisa?
B15: R1 | C15: R2
B16: ? | C16: sisa R1
A18: 1 | B18: proses panjang | F18: 1 | G18: ada risiko yang tidak mungkin dihabiskan: kebakaran
A19: 2 | B19: ada yg tidak termaintain dari rencana kita | F19: 2 | G19: sampai tingkat yg diterima
A20: 3 | B20: unpredictable risk yg sisa
G21: Tidak habis 100%:
A22: 1 | B22: tidak bisa habis 100% | F22: 1 | G22: Karena organisasi punya keterbatasan sumber daya.
A23: 2 | B23: analogi helm | F23: 2 | G23: Mengingat nomor 1, organisasi tidak bisa mengendalikan risiko 100% karena dia butuh untuk growth/tumbuh
G24: Kalau SEMUA sumber daya, SEMUA orang disuruh menurunkan risiko masing-masing, terus SIAPA YG KERJA?
G25: Kinerja A | I25: Risiko A | K25: Program pengentasa risiko 100%
G26: Kinerja B | I26: Risiko B | K26: Too much aware
G27: Tidak tercapai
F28: 3 | G28: Jadi akhirnya organisasi memilih risiko mana yang "layak" untuk dikendalikan
F29: 4 | G29: Prioritisasi Risiko
F31: 1 | G31: R1 | H31: Tertinggi
F32: 2 | G32: R2 | H32: No 2 tertinggi
F33: 3 | G33: R3 | H33: No 3 tertinggi
F34: 4 | G34: R4 | H34: …
L35: Mau invest/growth/mencapai tujuan ATAU dia mau mencegah terjadinya risiko?
G36: R25? | L36: Invest miliaran atau ratusan juta untuk membuat inovasi layanan yg masyarakat masih awam
G37: R30? | L37: 1. Risiko layanan baru tidak optimal | Q37: 20 | R37: 21
G38: R100? | L38: 2. Risiko reputasi akibat penerimaan masyarakat | Q38: Aktual: 18 | T38: 1. Monitor
F39: 5 | G39: SELERA RISIKO | Q39: IC -> | R39: 15 | T39: 2. Warning | U39: Sinyal/KRI
G40: Level risiko yang "diterima" oleh pimpinan organisasi | Q40: IC -> | R40: 12 | U40: KPI = IKU | V40: KRI = IRU | W40: KCI = IPU
G41: 20-25 | H41: Sangat Tinggi | J41: Risiko Gratifikasi pada meja PTS | U41: Sasaran | V41: MR | W41: SPIP
G42: .. | J42: "Saya ingin risiko itu tidak lebih dari 10" | U42: PK/RKT
G43: . | J43: 10
G44: 6-10 | H44: Rendah | J44: TERIMA | K44: (ga usah diapa-apain/ tidak usah dikendalikan)
G45: 1-5 | H45: Sangat Rendah | K45: IC 1 | L45: Library
K46: IC2
...

Sheet data
W1: Form Identifikasi Risiko
W3: Nama UPG | X3: UPG MAHKAMAH AGUNG
W4: Triwulan | X4: 3
W5: Tahun | X5: 2026
W7: Keterangan : * Wajib Diisi
A9: Klasifikasi Risiko | D9: Probabilitas Risiko | H9: Dampak Risiko | L9: Faktor Penyebab | O9: Level Risiko | T9: unit kerja | W9: No.* | X9: Unit Kerja yang memiliki risiko gratifikasi* | Y9: Potensi Terjadinya Gratifikasi* | Z9: Klasifikasi Risiko* | AA9: Probabilitas Potensi Gratifikasi* | AC9: Dampak Gratifikasi* | AE9: Alasan/Penyebab Utama | AH9: Level Risiko | AI9: Sistem Pengendalian dan Pengawasan yang ada | AK9: Rencana Mitigasi/Perbaikan
A10: Label | B10: Id | D10: Label | E10: Id | F10: level | H10: Label | I10: Id | J10: level | L10: Label | M10: Id | O10: lower limit | P10: upper limit | Q10: description | R10: id | T10: nama | U10: id | V10: rowgroup | AA10: Probabilitas Risiko* | AB10: Keterangan* | AC10: Dampak Risiko* | AD10: Keterangan* | AE10: No. | AF10: Klasifikasi Penyebab | AG10: Keterangan | AI10: No. | AJ10: Keterangan | AK10: No. | AL10: Keterangan | AN10: isfromsystem | AO10: originunitkerja | AP10: originpotensi | AQ10: originklasifikasirisiko | AR10: originprobabilitasrisiko | AS10: originprobabilitasrisikoketerangan | AT10: origindampakrisiko | AU10: originketerangandampakrisiko | AV10: originklasifikasipenyebab | AW10: originklasifikasipenyebabketerangan | AX10: originsistempengendaliandanpengawasanyangada | AY10: originrencanamitigasiperbaikan | AZ10: originitemuuid | BB10: klasifikasirisikoid | BC10: probabilitasrisikoid | BD10: dampakrisikoid | BE10: faktorpenyebabid | BF10: levelprobabilitas | BG10: leveldampak | BH10: levelrisiko | BI10: levelrisikoid | BJ10: levelrisikodesc | BK10: unitkerjaid | BM10: isfromprevperiod | BN10: src_tw | BO10: src_tahun | BP10: iskegiatanutama | BQ10: kegiatanutamaid | BR10: kegiatanutamavalue
A11: Sektor Pelayanan Publik | B11: 7 | D11: Level 1 - Hampir Tidak Terjadi | E11: 1 | F11: 1 | H11: Level 1 - Tidak Signifikan | I11: 1 | J11: 1 | L11: Pemahaman | M11: 1 | O11: 1 | P11: 5 | Q11: Level Risiko Sangat Rendah | R11: 2 | T11: Pengadilan Tinggi Aceh | U11: 30 | V11: =IF(ISBLANK($W11),IF(ISNUMBER(INDIRECT("S"&ROW($V11)-1)),INDIRECT("S"&ROW($V11)-1),1),$W11) -> 1 | AH11: =IF(ISNUMBER($BI11), $BH11&" - "&$BJ11,"") | BB11: =IF(ISBLANK($Z11),"",VLOOKUP($Z11,$A$11:$B$1010,2,FALSE)) | BC11: =IF(ISBLANK($AA11),"",VLOOKUP($AA11,$D$11:$E$1010,2,FALSE)) | BD11: =IF(ISBLANK($AC11),"",VLOOKUP($AC11,$H$11:$I$1010,2,FALSE)) | BE11: =IF(ISBLANK($AF11),"",VLOOKUP($AF11,$L$11:$M$1010,2,FALSE)) | BF11: =IF(ISNUMBER($BC11),VLOOKUP($BC11,$E$11:$F$1010,2,FALSE),"") | BG11: =IF(ISNUMBER($BD11),VLOOKUP($BD11,$I$11:$J$1010,2,FALSE),"") | BH11: =IF(AND(ISNUMBER($BF11),ISNUMBER($BG11)),$BF11*$BG11,"") | BI11: =IF(ISNUMBER($BH11),LOOKUP($BH11,lower_limit_level_risiko,id_level_risiko),"") | BJ11: =IF(ISNUMBER($BH11),LOOKUP($BH11,lower_limit_level_risiko,description_level_risiko),"") | BK11: =IF(ISBLANK($X11),"",VLOOKUP($X11,$T$11:$U$1010,2,FALSE)) | BS11: 30-07-2024
A12: Sektor Pengadaan Barang dan/atau Jasa | B12: 8 | D12: Level 2 - Jarang Terjadi | E12: 2 | F12: 2 | H12: Level 2 - Minor | I12: 2 | J12: 2 | L12: Penegakan Aturan | M12: 2 | O12: 1 | P12: 5 | Q12: Level Risiko Sangat Rendah | R12: 1 | T12: Mahkamah Agung | U12: 139 | V12: =IF(ISBLANK($W12),IF(ISNUMBER(INDIRECT("S"&ROW($V12)-1)),INDIRECT("S"&ROW($V12)-1),1),$W12) -> 1 | AH12: =IF(ISNUMBER($BI12), $BH12&" - "&$BJ12,"") | BB12: =IF(ISBLANK($Z12),"",VLOOKUP($Z12,$A$11:$B$1010,2,FALSE)) | BC12: =IF(ISBLANK($AA12),"",VLOOKUP($AA12,$D$11:$E$1010,2,FALSE)) | BD12: =IF(ISBLANK($AC12),"",VLOOKUP($AC12,$H$11:$I$1010,2,FALSE)) | BE12: =IF(ISBLANK($AF12),"",VLOOKUP($AF12,$L$11:$M$1010,2,FALSE)) | BF12: =IF(ISNUMBER($BC12),VLOOKUP($BC12,$E$11:$F$1010,2,FALSE),"") | BG12: =IF(ISNUMBER($BD12),VLOOKUP($BD12,$I$11:$J$1010,2,FALSE),"") | BH12: =IF(AND(ISNUMBER($BF12),ISNUMBER($BG12)),$BF12*$BG12,"") | BI12: =IF(ISNUMBER($BH12),LOOKUP($BH12,lower_limit_level_risiko,id_level_risiko),"") | BJ12: =IF(ISNUMBER($BH12),LOOKUP($BH12,lower_limit_level_risiko,description_level_risiko),"") | BK12: =IF(ISBLANK($X12),"",VLOOKUP($X12,$T$11:$U$1010,2,FALSE))
A13: Sektor Pengelolaan Sumber Daya Manusia | B13: 9 | D13: Level 3 - Kadang Terjadi | E13: 3 | F13: 3 | H13: Level 3 - Moderat | I13: 3 | J13: 3 | L13: Pemeriksaan | M13: 3 | O13: 6 | P13: 11 | Q13: Level Risiko Rendah | R13: 3 | T13: Pengadilan Tinggi d.i. Yogyakarta | U13: 347 | V13: =IF(ISBLANK($W13),IF(ISNUMBER(INDIRECT("S"&ROW($V13)-1)),INDIRECT("S"&ROW($V13)-1),1),$W13) -> 1 | AH13: =IF(ISNUMBER($BI13), $BH13&" - "&$BJ13,"") | BB13: =IF(ISBLANK($Z13),"",VLOOKUP($Z13,$A$11:$B$1010,2,FALSE)) | BC13: =IF(ISBLANK($AA13),"",VLOOKUP($AA13,$D$11:$E$1010,2,FALSE)) | BD13: =IF(ISBLANK($AC13),"",VLOOKUP($AC13,$H$11:$I$1010,2,FALSE)) | BE13: =IF(ISBLANK($AF13),"",VLOOKUP($AF13,$L$11:$M$1010,2,FALSE)) | BF13: =IF(ISNUMBER($BC13),VLOOKUP($BC13,$E$11:$F$1010,2,FALSE),"") | BG13: =IF(ISNUMBER($BD13),VLOOKUP($BD13,$I$11:$J$1010,2,FALSE),"") | BH13: =IF(AND(ISNUMBER($BF13),ISNUMBER($BG13)),$BF13*$BG13,"") | BI13: =IF(ISNUMBER($BH13),LOOKUP($BH13,lower_limit_level_risiko,id_level_risiko),"") | BJ13: =IF(ISNUMBER($BH13),LOOKUP($BH13,lower_limit_level_risiko,description_level_risiko),"") | BK13: =IF(ISBLANK($X13),"",VLOOKUP($X13,$T$11:$U$1010,2,FALSE))
A14: Sektor Perizinan | B14: 10 | D14: Level 4 - Sering Terjadi | E14: 4 | F14: 4 | H14: Level 4 - Signifikan | I14: 4 | J14: 4 | L14: Sistem | M14: 4 | O14: 12 | P14: 15 | Q14: Level Risiko Sedang | R14: 4 | T14: Pengadilan Tinggi Sulawesi Selatan | U14: 354 | V14: =IF(ISBLANK($W14),IF(ISNUMBER(INDIRECT("S"&ROW($V14)-1)),INDIRECT("S"&ROW($V14)-1),1),$W14) -> 1 | AH14: =IF(ISNUMBER($BI14), $BH14&" - "&$BJ14,"") | BB14: =IF(ISBLANK($Z14),"",VLOOKUP($Z14,$A$11:$B$1010,2,FALSE)) | BC14: =IF(ISBLANK($AA14),"",VLOOKUP($AA14,$D$11:$E$1010,2,FALSE)) | BD14: =IF(ISBLANK($AC14),"",VLOOKUP($AC14,$H$11:$I$1010,2,FALSE)) | BE14: =IF(ISBLANK($AF14),"",VLOOKUP($AF14,$L$11:$M$1010,2,FALSE)) | BF14: =IF(ISNUMBER($BC14),VLOOKUP($BC14,$E$11:$F$1010,2,FALSE),"") | BG14: =IF(ISNUMBER($BD14),VLOOKUP($BD14,$I$11:$J$1010,2,FALSE),"") | BH14: =IF(AND(ISNUMBER($BF14),ISNUMBER($BG14)),$BF14*$BG14,"") | BI14: =IF(ISNUMBER($BH14),LOOKUP($BH14,lower_limit_level_risiko,id_level_risiko),"") | BJ14: =IF(ISNUMBER($BH14),LOOKUP($BH14,lower_limit_level_risiko,description_level_risiko),"") | BK14: =IF(ISBLANK($X14),"",VLOOKUP($X14,$T$11:$U$1010,2,FALSE))
A15: Sektor Pemeriksaan/Audit | B15: 11 | D15: Level 5 - Hampir Pasti Terjadi | E15: 5 | F15: 5 | H15: Level 5 - Sangat Signifikan | I15: 5 | J15: 5 | L15: Lain-lain | M15: 5 | O15: 16 | P15: 19 | Q15: Level Risiko Tinggi | R15: 6 | T15: Pengadilan Tinggi Agama d.i. Yogyakarta | U15: 355 | V15: =IF(ISBLANK($W15),IF(ISNUMBER(INDIRECT("S"&ROW($V15)-1)),INDIRECT("S"&ROW($V15)-1),1),$W15) -> 1 | AH15: =IF(ISNUMBER($BI15), $BH15&" - "&$BJ15,"") | BB15: =IF(ISBLANK($Z15),"",VLOOKUP($Z15,$A$11:$B$1010,2,FALSE)) | BC15: =IF(ISBLANK($AA15),"",VLOOKUP($AA15,$D$11:$E$1010,2,FALSE)) | BD15: =IF(ISBLANK($AC15),"",VLOOKUP($AC15,$H$11:$I$1010,2,FALSE)) | BE15: =IF(ISBLANK($AF15),"",VLOOKUP($AF15,$L$11:$M$1010,2,FALSE)) | BF15: =IF(ISNUMBER($BC15),VLOOKUP($BC15,$E$11:$F$1010,2,FALSE),"") | BG15: =IF(ISNUMBER($BD15),VLOOKUP($BD15,$I$11:$J$1010,2,FALSE),"") | BH15: =IF(AND(ISNUMBER($BF15),ISNUMBER($BG15)),$BF15*$BG15,"") | BI15: =IF(ISNUMBER($BH15),LOOKUP($BH15,lower_limit_level_risiko,id_level_risiko),"") | BJ15: =IF(ISNUMBER($BH15),LOOKUP($BH15,lower_limit_level_risiko,description_level_risiko),"") | BK15: =IF(ISBLANK($X15),"",VLOOKUP($X15,$T$11:$U$1010,2,FALSE))
A16: Sektor Kewenangan Lainnya | B16: 12 | O16: 20 | P16: 25 | Q16: Level Risiko Sangat Tinggi | R16: 5 | T16: Pengadilan Tinggi Tata Usaha Negara Jakarta | U16: 356 | V16: =IF(ISBLANK($W16),IF(ISNUMBER(INDIRECT("S"&ROW($V16)-1)),INDIRECT("S"&ROW($V16)-1),1),$W16) -> 1 | AH16: =IF(ISNUMBER($BI16), $BH16&" - "&$BJ16,"") | BB16: =IF(ISBLANK($Z16),"",VLOOKUP($Z16,$A$11:$B$1010,2,FALSE)) | BC16: =IF(ISBLANK($AA16),"",VLOOKUP($AA16,$D$11:$E$1010,2,FALSE)) | BD16: =IF(ISBLANK($AC16),"",VLOOKUP($AC16,$H$11:$I$1010,2,FALSE)) | BE16: =IF(ISBLANK($AF16),"",VLOOKUP($AF16,$L$11:$M$1010,2,FALSE)) | BF16: =IF(ISNUMBER($BC16),VLOOKUP($BC16,$E$11:$F$1010,2,FALSE),"") | BG16: =IF(ISNUMBER($BD16),VLOOKUP($BD16,$I$11:$J$1010,2,FALSE),"") | BH16: =IF(AND(ISNUMBER($BF16),ISNUMBER($BG16)),$BF16*$BG16,"") | BI16: =IF(ISNUMBER($BH16),LOOKUP($BH16,lower_limit_level_risiko,id_level_risiko),"") | BJ16: =IF(ISNUMBER($BH16),LOOKUP($BH16,lower_limit_level_risiko,description_level_risiko),"") | BK16: =IF(ISBLANK($X16),"",VLOOKUP($X16,$T$11:$U$1010,2,FALSE))
O17: 20 | P17: 25 | Q17: Level Risiko Sangat Tinggi | R17: 7 | T17: Pengadilan Tinggi Maluku | U17: 357 | V17: =IF(ISBLANK($W17),IF(ISNUMBER(INDIRECT("S"&ROW($V17)-1)),INDIRECT("S"&ROW($V17)-1),1),$W17) -> 1 | AH17: =IF(ISNUMBER($BI17), $BH17&" - "&$BJ17,"") | BB17: =IF(ISBLANK($Z17),"",VLOOKUP($Z17,$A$11:$B$1010,2,FALSE)) | BC17: =IF(ISBLANK($AA17),"",VLOOKUP($AA17,$D$11:$E$1010,2,FALSE)) | BD17: =IF(ISBLANK($AC17),"",VLOOKUP($AC17,$H$11:$I$1010,2,FALSE)) | BE17: =IF(ISBLANK($AF17),"",VLOOKUP($AF17,$L$11:$M$1010,2,FALSE)) | BF17: =IF(ISNUMBER($BC17),VLOOKUP($BC17,$E$11:$F$1010,2,FALSE),"") | BG17: =IF(ISNUMBER($BD17),VLOOKUP($BD17,$I$11:$J$1010,2,FALSE),"") | BH17: =IF(AND(ISNUMBER($BF17),ISNUMBER($BG17)),$BF17*$BG17,"") | BI17: =IF(ISNUMBER($BH17),LOOKUP($BH17,lower_limit_level_risiko,id_level_risiko),"") | BJ17: =IF(ISNUMBER($BH17),LOOKUP($BH17,lower_limit_level_risiko,description_level_risiko),"") | BK17: =IF(ISBLANK($X17),"",VLOOKUP($X17,$T$11:$U$1010,2,FALSE))
T18: Pengadilan Tinggi Sulawesi Utara | U18: 363 | V18: =IF(ISBLANK($W18),IF(ISNUMBER(INDIRECT("S"&ROW($V18)-1)),INDIRECT("S"&ROW($V18)-1),1),$W18) -> 1 | AH18: =IF(ISNUMBER($BI18), $BH18&" - "&$BJ18,"") | BB18: =IF(ISBLANK($Z18),"",VLOOKUP($Z18,$A$11:$B$1010,2,FALSE)) | BC18: =IF(ISBLANK($AA18),"",VLOOKUP($AA18,$D$11:$E$1010,2,FALSE)) | BD18: =IF(ISBLANK($AC18),"",VLOOKUP($AC18,$H$11:$I$1010,2,FALSE)) | BE18: =IF(ISBLANK($AF18),"",VLOOKUP($AF18,$L$11:$M$1010,2,FALSE)) | BF18: =IF(ISNUMBER($BC18),VLOOKUP($BC18,$E$11:$F$1010,2,FALSE),"") | BG18: =IF(ISNUMBER($BD18),VLOOKUP($BD18,$I$11:$J$1010,2,FALSE),"") | BH18: =IF(AND(ISNUMBER($BF18),ISNUMBER($BG18)),$BF18*$BG18,"") | BI18: =IF(ISNUMBER($BH18),LOOKUP($BH18,lower_limit_level_risiko,id_level_risiko),"") | BJ18: =IF(ISNUMBER($BH18),LOOKUP($BH18,lower_limit_level_risiko,description_level_risiko),"") | BK18: =IF(ISBLANK($X18),"",VLOOKUP($X18,$T$11:$U$1010,2,FALSE))
T19: Pengadilan Militer | U19: 367 | V19: =IF(ISBLANK($W19),IF(ISNUMBER(INDIRECT("S"&ROW($V19)-1)),INDIRECT("S"&ROW($V19)-1),1),$W19) -> 1 | AH19: =IF(ISNUMBER($BI19), $BH19&" - "&$BJ19,"") | BB19: =IF(ISBLANK($Z19),"",VLOOKUP($Z19,$A$11:$B$1010,2,FALSE)) | BC19: =IF(ISBLANK($AA19),"",VLOOKUP($AA19,$D$11:$E$1010,2,FALSE)) | BD19: =IF(ISBLANK($AC19),"",VLOOKUP($AC19,$H$11:$I$1010,2,FALSE)) | BE19: =IF(ISBLANK($AF19),"",VLOOKUP($AF19,$L$11:$M$1010,2,FALSE)) | BF19: =IF(ISNUMBER($BC19),VLOOKUP($BC19,$E$11:$F$1010,2,FALSE),"") | BG19: =IF(ISNUMBER($BD19),VLOOKUP($BD19,$I$11:$J$1010,2,FALSE),"") | BH19: =IF(AND(ISNUMBER($BF19),ISNUMBER($BG19)),$BF19*$BG19,"") | BI19: =IF(ISNUMBER($BH19),LOOKUP($BH19,lower_limit_level_risiko,id_level_risiko),"") | BJ19: =IF(ISNUMBER($BH19),LOOKUP($BH19,lower_limit_level_risiko,description_level_risiko),"") | BK19: =IF(ISBLANK($X19),"",VLOOKUP($X19,$T$11:$U$1010,2,FALSE))
T20: Pengadilan Tinggi Tata Usaha Negara Medan | U20: 375 | V20: =IF(ISBLANK($W20),IF(ISNUMBER(INDIRECT("S"&ROW($V20)-1)),INDIRECT("S"&ROW($V20)-1),1),$W20) -> 1 | AH20: =IF(ISNUMBER($BI20), $BH20&" - "&$BJ20,"") | BB20: =IF(ISBLANK($Z20),"",VLOOKUP($Z20,$A$11:$B$1010,2,FALSE)) | BC20: =IF(ISBLANK($AA20),"",VLOOKUP($AA20,$D$11:$E$1010,2,FALSE)) | BD20: =IF(ISBLANK($AC20),"",VLOOKUP($AC20,$H$11:$I$1010,2,FALSE)) | BE20: =IF(ISBLANK($AF20),"",VLOOKUP($AF20,$L$11:$M$1010,2,FALSE)) | BF20: =IF(ISNUMBER($BC20),VLOOKUP($BC20,$E$11:$F$1010,2,FALSE),"") | BG20: =IF(ISNUMBER($BD20),VLOOKUP($BD20,$I$11:$J$1010,2,FALSE),"") | BH20: =IF(AND(ISNUMBER($BF20),ISNUMBER($BG20)),$BF20*$BG20,"") | BI20: =IF(ISNUMBER($BH20),LOOKUP($BH20,lower_limit_level_risiko,id_level_risiko),"") | BJ20: =IF(ISNUMBER($BH20),LOOKUP($BH20,lower_limit_level_risiko,description_level_risiko),"") | BK20: =IF(ISBLANK($X20),"",VLOOKUP($X20,$T$11:$U$1010,2,FALSE))
T21: Pengadilan Tinggi Bengkulu | U21: 376 | V21: =IF(ISBLANK($W21),IF(ISNUMBER(INDIRECT("S"&ROW($V21)-1)),INDIRECT("S"&ROW($V21)-1),1),$W21) -> 1 | AH21: =IF(ISNUMBER($BI21), $BH21&" - "&$BJ21,"") | BB21: =IF(ISBLANK($Z21),"",VLOOKUP($Z21,$A$11:$B$1010,2,FALSE)) | BC21: =IF(ISBLANK($AA21),"",VLOOKUP($AA21,$D$11:$E$1010,2,FALSE)) | BD21: =IF(ISBLANK($AC21),"",VLOOKUP($AC21,$H$11:$I$1010,2,FALSE)) | BE21: =IF(ISBLANK($AF21),"",VLOOKUP($AF21,$L$11:$M$1010,2,FALSE)) | BF21: =IF(ISNUMBER($BC21),VLOOKUP($BC21,$E$11:$F$1010,2,FALSE),"") | BG21: =IF(ISNUMBER($BD21),VLOOKUP($BD21,$I$11:$J$1010,2,FALSE),"") | BH21: =IF(AND(ISNUMBER($BF21),ISNUMBER($BG21)),$BF21*$BG21,"") | BI21: =IF(ISNUMBER($BH21),LOOKUP($BH21,lower_limit_level_risiko,id_level_risiko),"") | BJ21: =IF(ISNUMBER($BH21),LOOKUP($BH21,lower_limit_level_risiko,description_level_risiko),"") | BK21: =IF(ISBLANK($X21),"",VLOOKUP($X21,$T$11:$U$1010,2,FALSE))
T22: Pengadilan Tinggi Gorontalo | U22: 377 | V22: =IF(ISBLANK($W22),IF(ISNUMBER(INDIRECT("S"&ROW($V22)-1)),INDIRECT("S"&ROW($V22)-1),1),$W22) -> 1 | AH22: =IF(ISNUMBER($BI22), $BH22&" - "&$BJ22,"") | BB22: =IF(ISBLANK($Z22),"",VLOOKUP($Z22,$A$11:$B$1010,2,FALSE)) | BC22: =IF(ISBLANK($AA22),"",VLOOKUP($AA22,$D$11:$E$1010,2,FALSE)) | BD22: =IF(ISBLANK($AC22),"",VLOOKUP($AC22,$H$11:$I$1010,2,FALSE)) | BE22: =IF(ISBLANK($AF22),"",VLOOKUP($AF22,$L$11:$M$1010,2,FALSE)) | BF22: =IF(ISNUMBER($BC22),VLOOKUP($BC22,$E$11:$F$1010,2,FALSE),"") | BG22: =IF(ISNUMBER($BD22),VLOOKUP($BD22,$I$11:$J$1010,2,FALSE),"") | BH22: =IF(AND(ISNUMBER($BF22),ISNUMBER($BG22)),$BF22*$BG22,"") | BI22: =IF(ISNUMBER($BH22),LOOKUP($BH22,lower_limit_level_risiko,id_level_risiko),"") | BJ22: =IF(ISNUMBER($BH22),LOOKUP($BH22,lower_limit_level_risiko,description_level_risiko),"") | BK22: =IF(ISBLANK($X22),"",VLOOKUP($X22,$T$11:$U$1010,2,FALSE))
T23: Pengadilan Tinggi Agama Banten | U23: 378 | V23: =IF(ISBLANK($W23),IF(ISNUMBER(INDIRECT("S"&ROW($V23)-1)),INDIRECT("S"&ROW($V23)-1),1),$W23) -> 1 | AH23: =IF(ISNUMBER($BI23), $BH23&" - "&$BJ23,"") | BB23: =IF(ISBLANK($Z23),"",VLOOKUP($Z23,$A$11:$B$1010,2,FALSE)) | BC23: =IF(ISBLANK($AA23),"",VLOOKUP($AA23,$D$11:$E$1010,2,FALSE)) | BD23: =IF(ISBLANK($AC23),"",VLOOKUP($AC23,$H$11:$I$1010,2,FALSE)) | BE23: =IF(ISBLANK($AF23),"",VLOOKUP($AF23,$L$11:$M$1010,2,FALSE)) | BF23: =IF(ISNUMBER($BC23),VLOOKUP($BC23,$E$11:$F$1010,2,FALSE),"") | BG23: =IF(ISNUMBER($BD23),VLOOKUP($BD23,$I$11:$J$1010,2,FALSE),"") | BH23: =IF(AND(ISNUMBER($BF23),ISNUMBER($BG23)),$BF23*$BG23,"") | BI23: =IF(ISNUMBER($BH23),LOOKUP($BH23,lower_limit_level_risiko,id_level_risiko),"") | BJ23: =IF(ISNUMBER($BH23),LOOKUP($BH23,lower_limit_level_risiko,description_level_risiko),"") | BK23: =IF(ISBLANK($X23),"",VLOOKUP($X23,$T$11:$U$1010,2,FALSE))
T24: Pengadilan Tinggi Agama Jawa Timur | U24: 379 | V24: =IF(ISBLANK($W24),IF(ISNUMBER(INDIRECT("S"&ROW($V24)-1)),INDIRECT("S"&ROW($V24)-1),1),$W24) -> 1 | AH24: =IF(ISNUMBER($BI24), $BH24&" - "&$BJ24,"") | BB24: =IF(ISBLANK($Z24),"",VLOOKUP($Z24,$A$11:$B$1010,2,FALSE)) | BC24: =IF(ISBLANK($AA24),"",VLOOKUP($AA24,$D$11:$E$1010,2,FALSE)) | BD24: =IF(ISBLANK($AC24),"",VLOOKUP($AC24,$H$11:$I$1010,2,FALSE)) | BE24: =IF(ISBLANK($AF24),"",VLOOKUP($AF24,$L$11:$M$1010,2,FALSE)) | BF24: =IF(ISNUMBER($BC24),VLOOKUP($BC24,$E$11:$F$1010,2,FALSE),"") | BG24: =IF(ISNUMBER($BD24),VLOOKUP($BD24,$I$11:$J$1010,2,FALSE),"") | BH24: =IF(AND(ISNUMBER($BF24),ISNUMBER($BG24)),$BF24*$BG24,"") | BI24: =IF(ISNUMBER($BH24),LOOKUP($BH24,lower_limit_level_risiko,id_level_risiko),"") | BJ24: =IF(ISNUMBER($BH24),LOOKUP($BH24,lower_limit_level_risiko,description_level_risiko),"") | BK24: =IF(ISBLANK($X24),"",VLOOKUP($X24,$T$11:$U$1010,2,FALSE))
T25: Pengadilan Tinggi Agama Sulawesi Utara | U25: 380 | V25: =IF(ISBLANK($W25),IF(ISNUMBER(INDIRECT("S"&ROW($V25)-1)),INDIRECT("S"&ROW($V25)-1),1),$W25) -> 1 | AH25: =IF(ISNUMBER($BI25), $BH25&" - "&$BJ25,"") | BB25: =IF(ISBLANK($Z25),"",VLOOKUP($Z25,$A$11:$B$1010,2,FALSE)) | BC25: =IF(ISBLANK($AA25),"",VLOOKUP($AA25,$D$11:$E$1010,2,FALSE)) | BD25: =IF(ISBLANK($AC25),"",VLOOKUP($AC25,$H$11:$I$1010,2,FALSE)) | BE25: =IF(ISBLANK($AF25),"",VLOOKUP($AF25,$L$11:$M$1010,2,FALSE)) | BF25: =IF(ISNUMBER($BC25),VLOOKUP($BC25,$E$11:$F$1010,2,FALSE),"") | BG25: =IF(ISNUMBER($BD25),VLOOKUP($BD25,$I$11:$J$1010,2,FALSE),"") | BH25: =IF(AND(ISNUMBER($BF25),ISNUMBER($BG25)),$BF25*$BG25,"") | BI25: =IF(ISNUMBER($BH25),LOOKUP($BH25,lower_limit_level_risiko,id_level_risiko),"") | BJ25: =IF(ISNUMBER($BH25),LOOKUP($BH25,lower_limit_level_risiko,description_level_risiko),"") | BK25: =IF(ISBLANK($X25),"",VLOOKUP($X25,$T$11:$U$1010,2,FALSE))
T26: Pengadilan Tinggi Agama Nusa Tenggara Timur | U26: 381 | V26: =IF(ISBLANK($W26),IF(ISNUMBER(INDIRECT("S"&ROW($V26)-1)),INDIRECT("S"&ROW($V26)-1),1),$W26) -> 1 | AH26: =IF(ISNUMBER($BI26), $BH26&" - "&$BJ26,"") | BB26: =IF(ISBLANK($Z26),"",VLOOKUP($Z26,$A$11:$B$1010,2,FALSE)) | BC26: =IF(ISBLANK($AA26),"",VLOOKUP($AA26,$D$11:$E$1010,2,FALSE)) | BD26: =IF(ISBLANK($AC26),"",VLOOKUP($AC26,$H$11:$I$1010,2,FALSE)) | BE26: =IF(ISBLANK($AF26),"",VLOOKUP($AF26,$L$11:$M$1010,2,FALSE)) | BF26: =IF(ISNUMBER($BC26),VLOOKUP($BC26,$E$11:$F$1010,2,FALSE),"") | BG26: =IF(ISNUMBER($BD26),VLOOKUP($BD26,$I$11:$J$1010,2,FALSE),"") | BH26: =IF(AND(ISNUMBER($BF26),ISNUMBER($BG26)),$BF26*$BG26,"") | BI26: =IF(ISNUMBER($BH26),LOOKUP($BH26,lower_limit_level_risiko,id_level_risiko),"") | BJ26: =IF(ISNUMBER($BH26),LOOKUP($BH26,lower_limit_level_risiko,description_level_risiko),"") | BK26: =IF(ISBLANK($X26),"",VLOOKUP($X26,$T$11:$U$1010,2,FALSE))
T27: Pengadilan Tinggi Tata Usaha Negara Makassar | U27: 423 | V27: =IF(ISBLANK($W27),IF(ISNUMBER(INDIRECT("S"&ROW($V27)-1)),INDIRECT("S"&ROW($V27)-1),1),$W27) -> 1 | AH27: =IF(ISNUMBER($BI27), $BH27&" - "&$BJ27,"") | BB27: =IF(ISBLANK($Z27),"",VLOOKUP($Z27,$A$11:$B$1010,2,FALSE)) | BC27: =IF(ISBLANK($AA27),"",VLOOKUP($AA27,$D$11:$E$1010,2,FALSE)) | BD27: =IF(ISBLANK($AC27),"",VLOOKUP($AC27,$H$11:$I$1010,2,FALSE)) | BE27: =IF(ISBLANK($AF27),"",VLOOKUP($AF27,$L$11:$M$1010,2,FALSE)) | BF27: =IF(ISNUMBER($BC27),VLOOKUP($BC27,$E$11:$F$1010,2,FALSE),"") | BG27: =IF(ISNUMBER($BD27),VLOOKUP($BD27,$I$11:$J$1010,2,FALSE),"") | BH27: =IF(AND(ISNUMBER($BF27),ISNUMBER($BG27)),$BF27*$BG27,"") | BI27: =IF(ISNUMBER($BH27),LOOKUP($BH27,lower_limit_level_risiko,id_level_risiko),"") | BJ27: =IF(ISNUMBER($BH27),LOOKUP($BH27,lower_limit_level_risiko,description_level_risiko),"") | BK27: =IF(ISBLANK($X27),"",VLOOKUP($X27,$T$11:$U$1010,2,FALSE))
T28: Pengadilan Tinggi Sulawesi tengah | U28: 430 | V28: =IF(ISBLANK($W28),IF(ISNUMBER(INDIRECT("S"&ROW($V28)-1)),INDIRECT("S"&ROW($V28)-1),1),$W28) -> 1 | AH28: =IF(ISNUMBER($BI28), $BH28&" - "&$BJ28,"") | BB28: =IF(ISBLANK($Z28),"",VLOOKUP($Z28,$A$11:$B$1010,2,FALSE)) | BC28: =IF(ISBLANK($AA28),"",VLOOKUP($AA28,$D$11:$E$1010,2,FALSE)) | BD28: =IF(ISBLANK($AC28),"",VLOOKUP($AC28,$H$11:$I$1010,2,FALSE)) | BE28: =IF(ISBLANK($AF28),"",VLOOKUP($AF28,$L$11:$M$1010,2,FALSE)) | BF28: =IF(ISNUMBER($BC28),VLOOKUP($BC28,$E$11:$F$1010,2,FALSE),"") | BG28: =IF(ISNUMBER($BD28),VLOOKUP($BD28,$I$11:$J$1010,2,FALSE),"") | BH28: =IF(AND(ISNUMBER($BF28),ISNUMBER($BG28)),$BF28*$BG28,"") | BI28: =IF(ISNUMBER($BH28),LOOKUP($BH28,lower_limit_level_risiko,id_level_risiko),"") | BJ28: =IF(ISNUMBER($BH28),LOOKUP($BH28,lower_limit_level_risiko,description_level_risiko),"") | BK28: =IF(ISBLANK($X28),"",VLOOKUP($X28,$T$11:$U$1010,2,FALSE))
T29: Pengadilan Tinggi Jawa tengah | U29: 431 | V29: =IF(ISBLANK($W29),IF(ISNUMBER(INDIRECT("S"&ROW($V29)-1)),INDIRECT("S"&ROW($V29)-1),1),$W29) -> 1 | AH29: =IF(ISNUMBER($BI29), $BH29&" - "&$BJ29,"") | BB29: =IF(ISBLANK($Z29),"",VLOOKUP($Z29,$A$11:$B$1010,2,FALSE)) | BC29: =IF(ISBLANK($AA29),"",VLOOKUP($AA29,$D$11:$E$1010,2,FALSE)) | BD29: =IF(ISBLANK($AC29),"",VLOOKUP($AC29,$H$11:$I$1010,2,FALSE)) | BE29: =IF(ISBLANK($AF29),"",VLOOKUP($AF29,$L$11:$M$1010,2,FALSE)) | BF29: =IF(ISNUMBER($BC29),VLOOKUP($BC29,$E$11:$F$1010,2,FALSE),"") | BG29: =IF(ISNUMBER($BD29),VLOOKUP($BD29,$I$11:$J$1010,2,FALSE),"") | BH29: =IF(AND(ISNUMBER($BF29),ISNUMBER($BG29)),$BF29*$BG29,"") | BI29: =IF(ISNUMBER($BH29),LOOKUP($BH29,lower_limit_level_risiko,id_level_risiko),"") | BJ29: =IF(ISNUMBER($BH29),LOOKUP($BH29,lower_limit_level_risiko,description_level_risiko),"") | BK29: =IF(ISBLANK($X29),"",VLOOKUP($X29,$T$11:$U$1010,2,FALSE))
... T176: Pengadilan Agama Kajen | U176: 185584 | V176: =IF(ISBLANK($W176),IF(ISNUMBER(INDIRECT("S"&ROW($V176)-1)),INDIRECT("S"&ROW($V176)-1),1),$W176) -> 1 | AH176: =IF(ISNUMBER($BI176), $BH176&" - "&$BJ176,"") | BB176: =IF(ISBLANK($Z176),"",VLOOKUP($Z176,$A$11:$B$1010,2,FALSE)) | BC176: =IF(ISBLANK($AA176),"",VLOOKUP($AA176,$D$11:$E$1010,2,FALSE)) | BD176: =IF(ISBLANK($AC176),"",VLOOKUP($AC176,$H$11:$I$1010,2,FALSE)) | BE176: =IF(ISBLANK($AF176),"",VLOOKUP($AF176,$L$11:$M$1010,2,FALSE)) | BF176: =IF(ISNUMBER($BC176),VLOOKUP($BC176,$E$11:$F$1010,2,FALSE),"") | BG176: =IF(ISNUMBER($BD176),VLOOKUP($BD176,$I$11:$J$1010,2,FALSE),"") | BH176: =IF(AND(ISNUMBER($BF176),ISNUMBER($BG176)),$BF176*$BG176,"") | BI176: =IF(ISNUMBER($BH176),LOOKUP($BH176,lower_limit_level_risiko,id_level_risiko),"") | BJ176: =IF(ISNUMBER($BH176),LOOKUP($BH176,lower_limit_level_risiko,description_level_risiko),"") | BK176: =IF(ISBLANK($X176),"",VLOOKUP($X176,$T$11:$U$1010,2,FALSE))
V177: =IF(ISBLANK($W177),IF(ISNUMBER(INDIRECT("S"&ROW($V177)-1)),INDIRECT("S"&ROW($V177)-1),1),$W177) -> 1 | AH177: =IF(ISNUMBER($BI177), $BH177&" - "&$BJ177,"") | BB177: =IF(ISBLANK($Z177),"",VLOOKUP($Z177,$A$11:$B$1010,2,FALSE)) | BC177: =IF(ISBLANK($AA177),"",VLOOKUP($AA177,$D$11:$E$1010,2,FALSE)) | BD177: =IF(ISBLANK($AC177),"",VLOOKUP($AC177,$H$11:$I$1010,2,FALSE)) | BE177: =IF(ISBLANK($AF177),"",VLOOKUP($AF177,$L$11:$M$1010,2,FALSE)) | BF177: =IF(ISNUMBER($BC177),VLOOKUP($BC177,$E$11:$F$1010,2,FALSE),"") | BG177: =IF(ISNUMBER($BD177),VLOOKUP($BD177,$I$11:$J$1010,2,FALSE),"") | BH177: =IF(AND(ISNUMBER($BF177),ISNUMBER($BG177)),$BF177*$BG177,"") | BI177: =IF(ISNUMBER($BH177),LOOKUP($BH177,lower_limit_level_risiko,id_level_risiko),"") | BJ177: =IF(ISNUMBER($BH177),LOOKUP($BH177,lower_limit_level_risiko,description_level_risiko),"") | BK177: =IF(ISBLANK($X177),"",VLOOKUP($X177,$T$11:$U$1010,2,FALSE))
V178: =IF(ISBLANK($W178),IF(ISNUMBER(INDIRECT("S"&ROW($V178)-1)),INDIRECT("S"&ROW($V178)-1),1),$W178) -> 1 | AH178: =IF(ISNUMBER($BI178), $BH178&" - "&$BJ178,"") | BB178: =IF(ISBLANK($Z178),"",VLOOKUP($Z178,$A$11:$B$1010,2,FALSE)) | BC178: =IF(ISBLANK($AA178),"",VLOOKUP($AA178,$D$11:$E$1010,2,FALSE)) | BD178: =IF(ISBLANK($AC178),"",VLOOKUP($AC178,$H$11:$I$1010,2,FALSE)) | BE178: =IF(ISBLANK($AF178),"",VLOOKUP($AF178,$L$11:$M$1010,2,FALSE)) | BF178: =IF(ISNUMBER($BC178),VLOOKUP($BC178,$E$11:$F$1010,2,FALSE),"") | BG178: =IF(ISNUMBER($BD178),VLOOKUP($BD178,$I$11:$J$1010,2,FALSE),"") | BH178: =IF(AND(ISNUMBER($BF178),ISNUMBER($BG178)),$BF178*$BG178,"") | BI178: =IF(ISNUMBER($BH178),LOOKUP($BH178,lower_limit_level_risiko,id_level_risiko),"") | BJ178: =IF(ISNUMBER($BH178),LOOKUP($BH178,lower_limit_level_risiko,description_level_risiko),"") | BK178: =IF(ISBLANK($X178),"",VLOOKUP($X178,$T$11:$U$1010,2,FALSE))
V179: =IF(ISBLANK($W179),IF(ISNUMBER(INDIRECT("S"&ROW($V179)-1)),INDIRECT("S"&ROW($V179)-1),1),$W179) -> 1 | AH179: =IF(ISNUMBER($BI179), $BH179&" - "&$BJ179,"") | BB179: =IF(ISBLANK($Z179),"",VLOOKUP($Z179,$A$11:$B$1010,2,FALSE)) | BC179: =IF(ISBLANK($AA179),"",VLOOKUP($AA179,$D$11:$E$1010,2,FALSE)) | BD179: =IF(ISBLANK($AC179),"",VLOOKUP($AC179,$H$11:$I$1010,2,FALSE)) | BE179: =IF(ISBLANK($AF179),"",VLOOKUP($AF179,$L$11:$M$1010,2,FALSE)) | BF179: =IF(ISNUMBER($BC179),VLOOKUP($BC179,$E$11:$F$1010,2,FALSE),"") | BG179: =IF(ISNUMBER($BD179),VLOOKUP($BD179,$I$11:$J$1010,2,FALSE),"") | BH179: =IF(AND(ISNUMBER($BF179),ISNUMBER($BG179)),$BF179*$BG179,"") | BI179: =IF(ISNUMBER($BH179),LOOKUP($BH179,lower_limit_level_risiko,id_level_risiko),"") | BJ179: =IF(ISNUMBER($BH179),LOOKUP($BH179,lower_limit_level_risiko,description_level_risiko),"") | BK179: =IF(ISBLANK($X179),"",VLOOKUP($X179,$T$11:$U$1010,2,FALSE))
V180: =IF(ISBLANK($W180),IF(ISNUMBER(INDIRECT("S"&ROW($V180)-1)),INDIRECT("S"&ROW($V180)-1),1),$W180) -> 1 | AH180: =IF(ISNUMBER($BI180), $BH180&" - "&$BJ180,"") | BB180: =IF(ISBLANK($Z180),"",VLOOKUP($Z180,$A$11:$B$1010,2,FALSE)) | BC180: =IF(ISBLANK($AA180),"",VLOOKUP($AA180,$D$11:$E$1010,2,FALSE)) | BD180: =IF(ISBLANK($AC180),"",VLOOKUP($AC180,$H$11:$I$1010,2,FALSE)) | BE180: =IF(ISBLANK($AF180),"",VLOOKUP($AF180,$L$11:$M$1010,2,FALSE)) | BF180: =IF(ISNUMBER($BC180),VLOOKUP($BC180,$E$11:$F$1010,2,FALSE),"") | BG180: =IF(ISNUMBER($BD180),VLOOKUP($BD180,$I$11:$J$1010,2,FALSE),"") | BH180: =IF(AND(ISNUMBER($BF180),ISNUMBER($BG180)),$BF180*$BG180,"") | BI180: =IF(ISNUMBER($BH180),LOOKUP($BH180,lower_limit_level_risiko,id_level_risiko),"") | BJ180: =IF(ISNUMBER($BH180),LOOKUP($BH180,lower_limit_level_risiko,description_level_risiko),"") | BK180: =IF(ISBLANK($X180),"",VLOOKUP($X180,$T$11:$U$1010,2,FALSE))
V181: =IF(ISBLANK($W181),IF(ISNUMBER(INDIRECT("S"&ROW($V181)-1)),INDIRECT("S"&ROW($V181)-1),1),$W181) -> 1 | AH181: =IF(ISNUMBER($BI181), $BH181&" - "&$BJ181,"") | BB181: =IF(ISBLANK($Z181),"",VLOOKUP($Z181,$A$11:$B$1010,2,FALSE)) | BC181: =IF(ISBLANK($AA181),"",VLOOKUP($AA181,$D$11:$E$1010,2,FALSE)) | BD181: =IF(ISBLANK($AC181),"",VLOOKUP($AC181,$H$11:$I$1010,2,FALSE)) | BE181: =IF(ISBLANK($AF181),"",VLOOKUP($AF181,$L$11:$M$1010,2,FALSE)) | BF181: =IF(ISNUMBER($BC181),VLOOKUP($BC181,$E$11:$F$1010,2,FALSE),"") | BG181: =IF(ISNUMBER($BD181),VLOOKUP($BD181,$I$11:$J$1010,2,FALSE),"") | BH181: =IF(AND(ISNUMBER($BF181),ISNUMBER($BG181)),$BF181*$BG181,"") | BI181: =IF(ISNUMBER($BH181),LOOKUP($BH181,lower_limit_level_risiko,id_level_risiko),"") | BJ181: =IF(ISNUMBER($BH181),LOOKUP($BH181,lower_limit_level_risiko,description_level_risiko),"") | BK181: =IF(ISBLANK($X181),"",VLOOKUP($X181,$T$11:$U$1010,2,FALSE))
V182: =IF(ISBLANK($W182),IF(ISNUMBER(INDIRECT("S"&ROW($V182)-1)),INDIRECT("S"&ROW($V182)-1),1),$W182) -> 1 | AH182: =IF(ISNUMBER($BI182), $BH182&" - "&$BJ182,"") | BB182: =IF(ISBLANK($Z182),"",VLOOKUP($Z182,$A$11:$B$1010,2,FALSE)) | BC182: =IF(ISBLANK($AA182),"",VLOOKUP($AA182,$D$11:$E$1010,2,FALSE)) | BD182: =IF(ISBLANK($AC182),"",VLOOKUP($AC182,$H$11:$I$1010,2,FALSE)) | BE182: =IF(ISBLANK($AF182),"",VLOOKUP($AF182,$L$11:$M$1010,2,FALSE)) | BF182: =IF(ISNUMBER($BC182),VLOOKUP($BC182,$E$11:$F$1010,2,FALSE),"") | BG182: =IF(ISNUMBER($BD182),VLOOKUP($BD182,$I$11:$J$1010,2,FALSE),"") | BH182: =IF(AND(ISNUMBER($BF182),ISNUMBER($BG182)),$BF182*$BG182,"") | BI182: =IF(ISNUMBER($BH182),LOOKUP($BH182,lower_limit_level_risiko,id_level_risiko),"") | BJ182: =IF(ISNUMBER($BH182),LOOKUP($BH182,lower_limit_level_risiko,description_level_risiko),"") | BK182: =IF(ISBLANK($X182),"",VLOOKUP($X182,$T$11:$U$1010,2,FALSE))
V183: =IF(ISBLANK($W183),IF(ISNUMBER(INDIRECT("S"&ROW($V183)-1)),INDIRECT("S"&ROW($V183)-1),1),$W183) -> 1 | AH183: =IF(ISNUMBER($BI183), $BH183&" - "&$BJ183,"") | BB183: =IF(ISBLANK($Z183),"",VLOOKUP($Z183,$A$11:$B$1010,2,FALSE)) | BC183: =IF(ISBLANK($AA183),"",VLOOKUP($AA183,$D$11:$E$1010,2,FALSE)) | BD183: =IF(ISBLANK($AC183),"",VLOOKUP($AC183,$H$11:$I$1010,2,FALSE)) | BE183: =IF(ISBLANK($AF183),"",VLOOKUP($AF183,$L$11:$M$1010,2,FALSE)) | BF183: =IF(ISNUMBER($BC183),VLOOKUP($BC183,$E$11:$F$1010,2,FALSE),"") | BG183: =IF(ISNUMBER($BD183),VLOOKUP($BD183,$I$11:$J$1010,2,FALSE),"") | BH183: =IF(AND(ISNUMBER($BF183),ISNUMBER($BG183)),$BF183*$BG183,"") | BI183: =IF(ISNUMBER($BH183),LOOKUP($BH183,lower_limit_level_risiko,id_level_risiko),"") | BJ183: =IF(ISNUMBER($BH183),LOOKUP($BH183,lower_limit_level_risiko,description_level_risiko),"") | BK183: =IF(ISBLANK($X183),"",VLOOKUP($X183,$T$11:$U$1010,2,FALSE))
V184: =IF(ISBLANK($W184),IF(ISNUMBER(INDIRECT("S"&ROW($V184)-1)),INDIRECT("S"&ROW($V184)-1),1),$W184) -> 1 | AH184: =IF(ISNUMBER($BI184), $BH184&" - "&$BJ184,"") | BB184: =IF(ISBLANK($Z184),"",VLOOKUP($Z184,$A$11:$B$1010,2,FALSE)) | BC184: =IF(ISBLANK($AA184),"",VLOOKUP($AA184,$D$11:$E$1010,2,FALSE)) | BD184: =IF(ISBLANK($AC184),"",VLOOKUP($AC184,$H$11:$I$1010,2,FALSE)) | BE184: =IF(ISBLANK($AF184),"",VLOOKUP($AF184,$L$11:$M$1010,2,FALSE)) | BF184: =IF(ISNUMBER($BC184),VLOOKUP($BC184,$E$11:$F$1010,2,FALSE),"") | BG184: =IF(ISNUMBER($BD184),VLOOKUP($BD184,$I$11:$J$1010,2,FALSE),"") | BH184: =IF(AND(ISNUMBER($BF184),ISNUMBER($BG184)),$BF184*$BG184,"") | BI184: =IF(ISNUMBER($BH184),LOOKUP($BH184,lower_limit_level_risiko,id_level_risiko),"") | BJ184: =IF(ISNUMBER($BH184),LOOKUP($BH184,lower_limit_level_risiko,description_level_risiko),"") | BK184: =IF(ISBLANK($X184),"",VLOOKUP($X184,$T$11:$U$1010,2,FALSE))
V185: =IF(ISBLANK($W185),IF(ISNUMBER(INDIRECT("S"&ROW($V185)-1)),INDIRECT("S"&ROW($V185)-1),1),$W185) -> 1 | AH185: =IF(ISNUMBER($BI185), $BH185&" - "&$BJ185,"") | BB185: =IF(ISBLANK($Z185),"",VLOOKUP($Z185,$A$11:$B$1010,2,FALSE)) | BC185: =IF(ISBLANK($AA185),"",VLOOKUP($AA185,$D$11:$E$1010,2,FALSE)) | BD185: =IF(ISBLANK($AC185),"",VLOOKUP($AC185,$H$11:$I$1010,2,FALSE)) | BE185: =IF(ISBLANK($AF185),"",VLOOKUP($AF185,$L$11:$M$1010,2,FALSE)) | BF185: =IF(ISNUMBER($BC185),VLOOKUP($BC185,$E$11:$F$1010,2,FALSE),"") | BG185: =IF(ISNUMBER($BD185),VLOOKUP($BD185,$I$11:$J$1010,2,FALSE),"") | BH185: =IF(AND(ISNUMBER($BF185),ISNUMBER($BG185)),$BF185*$BG185,"") | BI185: =IF(ISNUMBER($BH185),LOOKUP($BH185,lower_limit_level_risiko,id_level_risiko),"") | BJ185: =IF(ISNUMBER($BH185),LOOKUP($BH185,lower_limit_level_risiko,description_level_risiko),"") | BK185: =IF(ISBLANK($X185),"",VLOOKUP($X185,$T$11:$U$1010,2,FALSE))
V186: =IF(ISBLANK($W186),IF(ISNUMBER(INDIRECT("S"&ROW($V186)-1)),INDIRECT("S"&ROW($V186)-1),1),$W186) -> 1 | AH186: =IF(ISNUMBER($BI186), $BH186&" - "&$BJ186,"") | BB186: =IF(ISBLANK($Z186),"",VLOOKUP($Z186,$A$11:$B$1010,2,FALSE)) | BC186: =IF(ISBLANK($AA186),"",VLOOKUP($AA186,$D$11:$E$1010,2,FALSE)) | BD186: =IF(ISBLANK($AC186),"",VLOOKUP($AC186,$H$11:$I$1010,2,FALSE)) | BE186: =IF(ISBLANK($AF186),"",VLOOKUP($AF186,$L$11:$M$1010,2,FALSE)) | BF186: =IF(ISNUMBER($BC186),VLOOKUP($BC186,$E$11:$F$1010,2,FALSE),"") | BG186: =IF(ISNUMBER($BD186),VLOOKUP($BD186,$I$11:$J$1010,2,FALSE),"") | BH186: =IF(AND(ISNUMBER($BF186),ISNUMBER($BG186)),$BF186*$BG186,"") | BI186: =IF(ISNUMBER($BH186),LOOKUP($BH186,lower_limit_level_risiko,id_level_risiko),"") | BJ186: =IF(ISNUMBER($BH186),LOOKUP($BH186,lower_limit_level_risiko,description_level_risiko),"") | BK186: =IF(ISBLANK($X186),"",VLOOKUP($X186,$T$11:$U$1010,2,FALSE))
V187: =IF(ISBLANK($W187),IF(ISNUMBER(INDIRECT("S"&ROW($V187)-1)),INDIRECT("S"&ROW($V187)-1),1),$W187) -> 1 | AH187: =IF(ISNUMBER($BI187), $BH187&" - "&$BJ187,"") | BB187: =IF(ISBLANK($Z187),"",VLOOKUP($Z187,$A$11:$B$1010,2,FALSE)) | BC187: =IF(ISBLANK($AA187),"",VLOOKUP($AA187,$D$11:$E$1010,2,FALSE)) | BD187: =IF(ISBLANK($AC187),"",VLOOKUP($AC187,$H$11:$I$1010,2,FALSE)) | BE187: =IF(ISBLANK($AF187),"",VLOOKUP($AF187,$L$11:$M$1010,2,FALSE)) | BF187: =IF(ISNUMBER($BC187),VLOOKUP($BC187,$E$11:$F$1010,2,FALSE),"") | BG187: =IF(ISNUMBER($BD187),VLOOKUP($BD187,$I$11:$J$1010,2,FALSE),"") | BH187: =IF(AND(ISNUMBER($BF187),ISNUMBER($BG187)),$BF187*$BG187,"") | BI187: =IF(ISNUMBER($BH187),LOOKUP($BH187,lower_limit_level_risiko,id_level_risiko),"") | BJ187: =IF(ISNUMBER($BH187),LOOKUP($BH187,lower_limit_level_risiko,description_level_risiko),"") | BK187: =IF(ISBLANK($X187),"",VLOOKUP($X187,$T$11:$U$1010,2,FALSE))
V188: =IF(ISBLANK($W188),IF(ISNUMBER(INDIRECT("S"&ROW($V188)-1)),INDIRECT("S"&ROW($V188)-1),1),$W188) -> 1 | AH188: =IF(ISNUMBER($BI188), $BH188&" - "&$BJ188,"") | BB188: =IF(ISBLANK($Z188),"",VLOOKUP($Z188,$A$11:$B$1010,2,FALSE)) | BC188: =IF(ISBLANK($AA188),"",VLOOKUP($AA188,$D$11:$E$1010,2,FALSE)) | BD188: =IF(ISBLANK($AC188),"",VLOOKUP($AC188,$H$11:$I$1010,2,FALSE)) | BE188: =IF(ISBLANK($AF188),"",VLOOKUP($AF188,$L$11:$M$1010,2,FALSE)) | BF188: =IF(ISNUMBER($BC188),VLOOKUP($BC188,$E$11:$F$1010,2,FALSE),"") | BG188: =IF(ISNUMBER($BD188),VLOOKUP($BD188,$I$11:$J$1010,2,FALSE),"") | BH188: =IF(AND(ISNUMBER($BF188),ISNUMBER($BG188)),$BF188*$BG188,"") | BI188: =IF(ISNUMBER($BH188),LOOKUP($BH188,lower_limit_level_risiko,id_level_risiko),"") | BJ188: =IF(ISNUMBER($BH188),LOOKUP($BH188,lower_limit_level_risiko,description_level_risiko),"") | BK188: =IF(ISBLANK($X188),"",VLOOKUP($X188,$T$11:$U$1010,2,FALSE))
... V1010: =IF(ISBLANK($W1010),IF(ISNUMBER(INDIRECT("S"&ROW($V1010)-1)),INDIRECT("S"&ROW($V1010)-1),1),$W1010) -> 1 | AH1010: =IF(ISNUMBER($BI1010), $BH1010&" - "&$BJ1010,"") | BB1010: =IF(ISBLANK($Z1010),"",VLOOKUP($Z1010,$A$11:$B$1010,2,FALSE)) | BC1010: =IF(ISBLANK($AA1010),"",VLOOKUP($AA1010,$D$11:$E$1010,2,FALSE)) | BD1010: =IF(ISBLANK($AC1010),"",VLOOKUP($AC1010,$H$11:$I$1010,2,FALSE)) | BE1010: =IF(ISBLANK($AF1010),"",VLOOKUP($AF1010,$L$11:$M$1010,2,FALSE)) | BF1010: =IF(ISNUMBER($BC1010),VLOOKUP($BC1010,$E$11:$F$1010,2,FALSE),"") | BG1010: =IF(ISNUMBER($BD1010),VLOOKUP($BD1010,$I$11:$J$1010,2,FALSE),"") | BH1010: =IF(AND(ISNUMBER($BF1010),ISNUMBER($BG1010)),$BF1010*$BG1010,"") | BI1010: =IF(ISNUMBER($BH1010),LOOKUP($BH1010,lower_limit_level_risiko,id_level_risiko),"") | BJ1010: =IF(ISNUMBER($BH1010),LOOKUP($BH1010,lower_limit_level_risiko,description_level_risiko),"") | BK1010: =IF(ISBLANK($X1010),"",VLOOKUP($X1010,$T$11:$U$1010,2,FALSE))

Sheet Risk Register 2026
A1: FORM RISK REGISTER 2026
A2: Nama UPG | B2: UPG MAHKAMAH AGUNG | D2: Triwulan | E2: 3 | F2: Tahun | G2: 2026
A3: Keterangan: * Wajib diisi. Sheet ini standalone (tidak terhubung ke sheet lain). Kolom abu-abu (Q:Z) berisi kode/skor hasil kalkulasi otomatis dari tabel referensi di kanan (AE:AV), kecuali kolom Z (unitkerjaid) yang diisi manual bila diperlukan.
A4: No. | B4: Unit Kerja yang memiliki risiko gratifikasi | C4: Potensi Terjadinya Gratifikasi | D4: Klasifikasi Risiko | E4: Probabilitas Potensi Gratifikasi | G4: Dampak Gratifikasi | I4: Alasan/Penyebab Utama | L4: Level Risiko | M4: Sistem Pengendalian dan Pengawasan yang ada | O4: Rencana Mitigasi/Perbaikan | Q4: klasifikasirisikoid | R4: probabilitasrisikoid | S4: dampakrisikoid | T4: faktorpenyebabid | U4: levelprobabilitas | V4: leveldampak | W4: levelrisiko | X4: levelrisikoid | Y4: levelrisikodesc | AA4: Tahun Analisis | AB4: Daftar Satker Relevan (Hasil Analisis 2024–2025) | AC4: PIC | AE4: Klasifikasi Risiko | AH4: Probabilitas Risiko | AL4: Dampak Risiko | AP4: Faktor Penyebab | AS4: Level Risiko
E5: Probabilitas Risiko | F5: Keterangan | G5: Dampak Risiko | H5: Keterangan | I5: No. | J5: Klasifikasi Penyebab | K5: Keterangan | M5: No. | N5: Keterangan | O5: No. | P5: Keterangan | AA5: 2024 | AB5: Pengadilan Negeri Palembang | AC5: 5 | AE5: Label | AF5: Id | AH5: Label | AI5: Id | AJ5: Level | AL5: Label | AM5: Id | AN5: Level | AP5: Label | AQ5: Id | AS5: Lower Limit | AT5: Upper Limit | AU5: Description | AV5: Id
A6: =ROW()-5 -> 1 | B6: Pengadilan Negeri Palembang | C6: Permohonan Informasi - Informasi | D6: Sektor Pelayanan Publik | E6: Level 1 - Hampir Tidak Terjadi | F6: - | G6: Level 2 - Minor | H6: Turunnya kepercayaan publik terhadap lembaga peradilan | J6: Lain-lain | K6: 1. Sistem: kurangnya pengawasan dari pimpinan. 2. Individu: Keinginan untuk mendapatkan insentif tambahan di luar dari yang seharusnya . | L6: =IF(ISNUMBER(X6),W6&" - "&Y6,"") -> 2 - Level Risiko Sangat Rendah | N6: 1. Sudah dibuatkan SOP tersendiri mengenai peminjaman berkas, 2. Adanya CCTV untuk mengawasi para pelaksana kearsipan, 3. Disediakannya buku register peminjaman berkas baik manual maupun melalui SIPP… | P6: - | Q6: =IF(ISBLANK(D6),"",VLOOKUP(D6,$AE$6:$AF$9,2,FALSE)) -> 7 | R6: =IF(ISBLANK(E6),"",VLOOKUP(E6,$AH$6:$AI$9,2,FALSE)) -> 1 | S6: =IF(ISBLANK(G6),"",VLOOKUP(G6,$AL$6:$AM$9,2,FALSE)) -> 2 | T6: =IF(ISBLANK(J6),"",VLOOKUP(J6,$AP$6:$AQ$9,2,FALSE)) -> #N/A | U6: =IF(ISNUMBER(R6),VLOOKUP(R6,$AI$6:$AJ$9,2,FALSE),"") -> 1 | V6: =IF(ISNUMBER(S6),VLOOKUP(S6,$AM$6:$AN$9,2,FALSE),"") -> 2 | W6: =IF(AND(ISNUMBER(U6),ISNUMBER(V6)),U6*V6,"") -> 2 | X6: =IF(ISNUMBER(W6),LOOKUP(W6,$AS$6:$AS$9,$AV$6:$AV$9),"") -> 2 | Y6: =IF(ISNUMBER(W6),LOOKUP(W6,$AS$6:$AS$9,$AU$6:$AU$9),"") -> Level Risiko Sangat Rendah | AA6: 2024 | AB6: Pengadilan Negeri Pati | AC6: 4 | AE6: Sektor Pelayanan Publik | AF6: 7 | AH6: Level 1 - Hampir Tidak Terjadi | AI6: 1 | AJ6: 1 | AL6: Level 1 - Tidak Signifikan | AM6: 1 | AN6: 1 | AP6: Pemahaman | AQ6: 1 | AS6: 1 | AT6: 5 | AU6: Level Risiko Sangat Rendah | AV6: 2
A7: 1 | B7: Pengadilan Negeri Palembang | C7: Belanja Barang – Persediaan Barang | D7: Sektor Pengadaan Barang dan/atau Jasa | E7: Level 2 - Jarang Terjadi | G7: Level 3 - Moderat | H7: Turunnya kepercayaan publik terhadap lembaga peradilan | J7: Sistem | K7: 1. Sistem: kurangnya pengawasan dari pimpinan, yaitu KPN, WKPN, Sekretaris, dan Kasubag. 2. Individu: keinginan personel PN untuk mendapatkan insentif di luar dari yang seharusnya. | L7: =IF(ISNUMBER(X7),W7&" - "&Y7,"") -> 6 - Level Risiko Rendah | N7: 1. Pihak yang membeli, membayar, dan menerima barang tidak dilakukan oleh orang yang sama. 2. Sudah ada Hakim Pengawas Bidang. | Q7: =IF(ISBLANK(D7),"",VLOOKUP(D7,$AE$6:$AF$9,2,FALSE)) -> 8 | R7: =IF(ISBLANK(E7),"",VLOOKUP(E7,$AH$6:$AI$9,2,FALSE)) -> 2 | S7: =IF(ISBLANK(G7),"",VLOOKUP(G7,$AL$6:$AM$9,2,FALSE)) -> 3 | T7: =IF(ISBLANK(J7),"",VLOOKUP(J7,$AP$6:$AQ$9,2,FALSE)) -> #N/A | U7: =IF(ISNUMBER(R7),VLOOKUP(R7,$AI$6:$AJ$9,2,FALSE),"") -> 2 | V7: =IF(ISNUMBER(S7),VLOOKUP(S7,$AM$6:$AN$9,2,FALSE),"") -> 3 | W7: =IF(AND(ISNUMBER(U7),ISNUMBER(V7)),U7*V7,"") -> 6 | X7: =IF(ISNUMBER(W7),LOOKUP(W7,$AS$6:$AS$9,$AV$6:$AV$9),"") -> 3 | Y7: =IF(ISNUMBER(W7),LOOKUP(W7,$AS$6:$AS$9,$AU$6:$AU$9),"") -> Level Risiko Rendah
A8: =A7+1 -> 2 | C8: Pembayaran Kegiatan Belanja Modal – SPM | D8: Sektor Pengadaan Barang dan/atau Jasa | E8: Level 3 - Kadang Terjadi | G8: Level 3 - Moderat | H8: Turunnya kepercayaan publik terhadap lembaga peradilan | J8: Sistem | K8: 1. Sistem: kurangnya pengawasan dari pimpinan, yaitu KPN, WKPN, Sekretaris, dan Kasubag. 2. Individu: keinginan personel PN untuk mendapatkan insentif di luar dari yang seharusnya. | L8: =IF(ISNUMBER(X8),W8&" - "&Y8,"") -> 9 - Level Risiko Rendah | N8: 1. Pihak yang membeli, membayar, dan menerima barang tidak dilakukan oleh orang yang sama. 2. Sudah ada Hakim Pengawas Bidang. | Q8: =IF(ISBLANK(D8),"",VLOOKUP(D8,$AE$6:$AF$9,2,FALSE)) -> 8 | R8: =IF(ISBLANK(E8),"",VLOOKUP(E8,$AH$6:$AI$9,2,FALSE)) -> 3 | S8: =IF(ISBLANK(G8),"",VLOOKUP(G8,$AL$6:$AM$9,2,FALSE)) -> 3 | T8: =IF(ISBLANK(J8),"",VLOOKUP(J8,$AP$6:$AQ$9,2,FALSE)) -> #N/A | U8: =IF(ISNUMBER(R8),VLOOKUP(R8,$AI$6:$AJ$9,2,FALSE),"") -> 3 | V8: =IF(ISNUMBER(S8),VLOOKUP(S8,$AM$6:$AN$9,2,FALSE),"") -> 3 | W8: =IF(AND(ISNUMBER(U8),ISNUMBER(V8)),U8*V8,"") -> 9 | X8: =IF(ISNUMBER(W8),LOOKUP(W8,$AS$6:$AS$9,$AV$6:$AV$9),"") -> 3 | Y8: =IF(ISNUMBER(W8),LOOKUP(W8,$AS$6:$AS$9,$AU$6:$AU$9),"") -> Level Risiko Rendah | AA8: 2024 | AB8: Pengadilan Negeri Bogor | AC8: 3 | AE8: Sektor Pengadaan Barang dan/atau Jasa | AF8: 8 | AH8: Level 2 - Jarang Terjadi | AI8: 2 | AJ8: 2 | AL8: Level 2 - Minor | AM8: 2 | AN8: 2 | AP8: Penegakan Aturan | AQ8: 2 | AS8: 6 | AT8: 11 | AU8: Level Risiko Rendah | AV8: 3
A9: =A8+1 -> 3 | C9: Pembayaran Hak-Hak Pegawai – SPM | D9: Sektor Pengadaan Barang dan/atau Jasa | E9: Level 2 - Jarang Terjadi | G9: Level 1 - Tidak Signifikan | H9: Turunnya kepercayaan publik terhadap lembaga peradilan | J9: Sistem | K9: 1. Sistem: kurangnya pengawasan dari pimpinan, yaitu KPN, WKPN, Sekretaris, dan Kasubag. 2. Individu: keinginan personel PN untuk mendapatkan insentif di luar dari yang seharusnya. | L9: =IF(ISNUMBER(X9),W9&" - "&Y9,"") -> 2 - Level Risiko Sangat Rendah | N9: 1. Pihak yang membeli, membayar, dan menerima barang tidak dilakukan oleh orang yang sama. 2. Sudah ada Hakim Pengawas Bidang. | Q9: =IF(ISBLANK(D9),"",VLOOKUP(D9,$AE$6:$AF$9,2,FALSE)) -> 8 | R9: =IF(ISBLANK(E9),"",VLOOKUP(E9,$AH$6:$AI$9,2,FALSE)) -> 2 | S9: =IF(ISBLANK(G9),"",VLOOKUP(G9,$AL$6:$AM$9,2,FALSE)) -> 1 | T9: =IF(ISBLANK(J9),"",VLOOKUP(J9,$AP$6:$AQ$9,2,FALSE)) -> #N/A | U9: =IF(ISNUMBER(R9),VLOOKUP(R9,$AI$6:$AJ$9,2,FALSE),"") -> 2 | V9: =IF(ISNUMBER(S9),VLOOKUP(S9,$AM$6:$AN$9,2,FALSE),"") -> 1 | W9: =IF(AND(ISNUMBER(U9),ISNUMBER(V9)),U9*V9,"") -> 2 | X9: =IF(ISNUMBER(W9),LOOKUP(W9,$AS$6:$AS$9,$AV$6:$AV$9),"") -> 2 | Y9: =IF(ISNUMBER(W9),LOOKUP(W9,$AS$6:$AS$9,$AU$6:$AU$9),"") -> Level Risiko Sangat Rendah | AA9: 2024 | AB9: Pengadilan Negeri Wates | AC9: 2 | AE9: Sektor Pengelolaan Sumber Daya Manusia | AF9: 9 | AH9: Level 3 - Kadang Terjadi | AI9: 3 | AJ9: 3 | AL9: Level 3 - Moderat | AM9: 3 | AN9: 3 | AP9: Pemeriksaan | AQ9: 3 | AS9: 12 | AT9: 15 | AU9: Level Risiko Sedang | AV9: 4
A10: =A9+1 -> 4 | B10: Pengadilan Negeri Bandung | C10: Surat Keterangan Tidak Tersangkut Perkara – menerima dan meneliti berkas permohonan melalui aplikasi ERATERANG; membuat, memeriksa, memverifikasi, dan menandatangani konsep surat keterangan; mencatat dalam buku register; mengarahkan pembayaran PNBP melalui Bank BTN; menerima bukti setor; serta menyerahkan surat keterangan kepada pemohon. | D10: Sektor Pelayanan Publik | E10: Level 1 - Hampir Tidak Terjadi | G10: Level 2 - Minor | H10: Turunnya kepercayaan publik terhadap lembaga peradilan | J10: Lain-lain | K10: Kurangnya integritas dan profesionalitas. | L10: =IF(ISNUMBER(X10),W10&" - "&Y10,"") -> 2 - Level Risiko Sangat Rendah | N10: 1. SOP Surat Keterangan Tidak Tersangkut Perkara. 2. Penetapan Ketua PN Bandung Nomor 1067/KPN.W11-U1/HK.02/1/2024 tentang biaya PNBP dan panjar perkara | Q10: =IF(ISBLANK(D10),"",VLOOKUP(D10,$AE$6:$AF$9,2,FALSE)) -> 7 | R10: =IF(ISBLANK(E10),"",VLOOKUP(E10,$AH$6:$AI$9,2,FALSE)) -> 1 | S10: =IF(ISBLANK(G10),"",VLOOKUP(G10,$AL$6:$AM$9,2,FALSE)) -> 2 | T10: =IF(ISBLANK(J10),"",VLOOKUP(J10,$AP$6:$AQ$9,2,FALSE)) -> #N/A | U10: =IF(ISNUMBER(R10),VLOOKUP(R10,$AI$6:$AJ$9,2,FALSE),"") -> 1 | V10: =IF(ISNUMBER(S10),VLOOKUP(S10,$AM$6:$AN$9,2,FALSE),"") -> 2 | W10: =IF(AND(ISNUMBER(U10),ISNUMBER(V10)),U10*V10,"") -> 2 | X10: =IF(ISNUMBER(W10),LOOKUP(W10,$AS$6:$AS$9,$AV$6:$AV$9),"") -> 2 | Y10: =IF(ISNUMBER(W10),LOOKUP(W10,$AS$6:$AS$9,$AU$6:$AU$9),"") -> Level Risiko Sangat Rendah | AA10: 2024 | AB10: Pengadilan Negeri Ambon | AC10: 1 | AE10: Sektor Perizinan | AF10: 10 | AH10: Level 4 - Sering Terjadi | AI10: 4 | AJ10: 4 | AL10: Level 4 - Signifikan | AM10: 4 | AN10: 4 | AP10: Sistem | AQ10: 4 | AS10: 16 | AT10: 19 | AU10: Level Risiko Tinggi | AV10: 6
A11: =A10+1 -> 5 | C11: Legalisasi Surat Akta di Bawah Tangan (Waarmerking) – menerima dan meneliti kelengkapan permohonan; memverifikasi berkas; membuat dan memeriksa catatan waarmerking; menandatangani catatan dengan dihadiri pemohon; mencatat dalam buku register; mengarahkan pembayaran PNBP melalui Bank BTN; menerima bukti setor; serta menyerahkan surat pernyataan ahli waris kepada pemohon. | D11: Sektor Pelayanan Publik | E11: Level 2 - Jarang Terjadi | G11: Level 2 - Minor | H11: 1. Turunnya kepercayaan publik terhadap lembaga peradilan 2. Merusak citra lembaga peradilan | J11: Lain-lain | K11: Kurangnya integritas dan profesionalitas. | L11: =IF(ISNUMBER(X11),W11&" - "&Y11,"") -> 4 - Level Risiko Sangat Rendah | N11: 1. Buku II Mahkamah Agung RI tentang Pedoman Pelaksanaan Tugas dan Administrasi Peradilan. 2. SOP Legalisasi Surat Akta di Bawah Tangan (Waarmerking). | Q11: =IF(ISBLANK(D11),"",VLOOKUP(D11,$AE$6:$AF$9,2,FALSE)) -> 7 | R11: =IF(ISBLANK(E11),"",VLOOKUP(E11,$AH$6:$AI$9,2,FALSE)) -> 2 | S11: =IF(ISBLANK(G11),"",VLOOKUP(G11,$AL$6:$AM$9,2,FALSE)) -> 2 | T11: =IF(ISBLANK(J11),"",VLOOKUP(J11,$AP$6:$AQ$9,2,FALSE)) -> #N/A | U11: =IF(ISNUMBER(R11),VLOOKUP(R11,$AI$6:$AJ$9,2,FALSE),"") -> 2 | V11: =IF(ISNUMBER(S11),VLOOKUP(S11,$AM$6:$AN$9,2,FALSE),"") -> 2 | W11: =IF(AND(ISNUMBER(U11),ISNUMBER(V11)),U11*V11,"") -> 4 | X11: =IF(ISNUMBER(W11),LOOKUP(W11,$AS$6:$AS$9,$AV$6:$AV$9),"") -> 2 | Y11: =IF(ISNUMBER(W11),LOOKUP(W11,$AS$6:$AS$9,$AU$6:$AU$9),"") -> Level Risiko Sangat Rendah | AA11: 2024 | AB11: Pengadilan Tata Usaha Negara Serang | AC11: 5 | AE11: Sektor Pemeriksaan/Audit | AF11: 11 | AH11: Level 5 - Hampir Pasti Terjadi | AI11: 5 | AJ11: 5 | AL11: Level 5 - Sangat Signifikan | AM11: 5 | AN11: 5 | AP11: Lain-lain | AQ11: 5 | AS11: 20 | AT11: 25 | AU11: Level Risiko Sangat Tinggi | AV11: 5
A12: =A11+1 -> 6 | C12: Pelaksanaan Pengadaan Barang dan Jasa – perencanaan pengadaan; persiapan pengadaan melalui swakelola atau penyedia; pelaksanaan pemilihan; pelaksanaan kontrak; pembayaran; pengawasan; pertanggungjawaban; serta serah terima hasil pekerjaan. | D12: Sektor Pengadaan Barang dan/atau Jasa | E12: Level 3 - Kadang Terjadi | G12: Level 2 - Minor | H12: 1. Turunnya kepercayaan publik terhadap satuan kerja dan Mahkamah Agung. 2. Terjadinya kerugian negara lebih dari Rp10 juta, dengan pagu belanja barang satker tahun 2023 sejumlah Rp3 miliar. 3. Adanya keluhan pihak ketiga/rekanan melalui sistem pengaduan internal. | J12: Sistem | K12: 1. Kurangnya pengawasan atau pengendalian internal. 2. Adanya dorongan untuk melakukan fraud karena kebutuhan keuangan pribadi atau keserakahan semata | L12: =IF(ISNUMBER(X12),W12&" - "&Y12,"") -> 6 - Level Risiko Rendah | N12: 1. Rekonsiliasi/pemeriksaan UAKPA, KPB, Kasubbag TU dan Keuangan, serta Hakim Pengawas Bidang minimal satu kali setiap bulan. 2. Rekonsiliasi/pemeriksaan koordinator wilayah dan pusat setiap semester. 3. UU Nomor 17 Tahun 2003 tentang Keuangan Negara. 4. UU Nomor 1 Tahun 2004 tentang Perbendaharaan Negara. 5. Perpres Nomor 12 Tahun 2021 tentang Pengadaan Barang/Jasa Pemerintah. 6. Keputusan Sekretaris MA RI Nomor 657/SEK/SK/X/2018. 7. SOP Pengadaan Barang/Jasa. 8. SOP Pertanggungjawaban Belanja terhadap Pihak Ketiga/Rekanan. | Q12: =IF(ISBLANK(D12),"",VLOOKUP(D12,$AE$6:$AF$9,2,FALSE)) -> 8 | R12: =IF(ISBLANK(E12),"",VLOOKUP(E12,$AH$6:$AI$9,2,FALSE)) -> 3 | S12: =IF(ISBLANK(G12),"",VLOOKUP(G12,$AL$6:$AM$9,2,FALSE)) -> 2 | T12: =IF(ISBLANK(J12),"",VLOOKUP(J12,$AP$6:$AQ$9,2,FALSE)) -> #N/A | U12: =IF(ISNUMBER(R12),VLOOKUP(R12,$AI$6:$AJ$9,2,FALSE),"") -> 3 | V12: =IF(ISNUMBER(S12),VLOOKUP(S12,$AM$6:$AN$9,2,FALSE),"") -> 2 | W12: =IF(AND(ISNUMBER(U12),ISNUMBER(V12)),U12*V12,"") -> 6 | X12: =IF(ISNUMBER(W12),LOOKUP(W12,$AS$6:$AS$9,$AV$6:$AV$9),"") -> 3 | Y12: =IF(ISNUMBER(W12),LOOKUP(W12,$AS$6:$AS$9,$AU$6:$AU$9),"") -> Level Risiko Rendah | AA12: 2024 | AB12: Pengadilan Tata Usaha Negara Tanjung Pinang | AC12: 4 | AE12: Sektor Lainnya | AF12: 12
